# Snapshot report for `test/prefer-error-cause.mjs`

The actual snapshot is saved in `prefer-error-cause.mjs.snap`.

Generated by [AVA](https://avajs.dev).

## Invalid #1
      1 | try {} catch (error) { throw new Error(); }

> Error 1/1

    `␊
    > 1 | try {} catch (error) { throw new Error(); }␊
        |        ^^^^^^^^^^^^^^^^^^^^^^^^^^^^^^^^^^^^ Prefer specifying an old error as \`cause\` option when rethrowing the error.␊
    `

## Invalid #2
      1 | try {} catch (error) { throw new Error; }

> Error 1/1

    `␊
    > 1 | try {} catch (error) { throw new Error; }␊
        |        ^^^^^^^^^^^^^^^^^^^^^^^^^^^^^^^^^^ Prefer specifying an old error as \`cause\` option when rethrowing the error.␊
    `

## Invalid #3
      1 | try {} catch { throw new Error(); }

> Error 1/1

    `␊
    > 1 | try {} catch { throw new Error(); }␊
        |        ^^^^^^^^^^^^^^^^^^^^^^^^^^^^ Prefer specifying an old error as \`cause\` option when rethrowing the error.␊
    `

## Invalid #4
      1 | try {} catch { throw new Error; }

> Error 1/1

    `␊
    > 1 | try {} catch { throw new Error; }␊
        |        ^^^^^^^^^^^^^^^^^^^^^^^^^^ Prefer specifying an old error as \`cause\` option when rethrowing the error.␊
    `

## Invalid #5
      1 | try {} catch (oldError) {
      2 | 	let error;
      3 | 	error = new Error;
      4 | 	throw error;
      5 | }

> Error 1/1

    `␊
    > 1 | try {} catch (oldError) {␊
        |        ^^^^^^^^^^^^^^^^^^␊
    > 2 | 	let error;␊
        | ^^^^^^^^^^^␊
    > 3 | 	error = new Error;␊
        | ^^^^^^^^^^^␊
    > 4 | 	throw error;␊
        | ^^^^^^^^^^^␊
    > 5 | }␊
        | ^^ Prefer specifying an old error as \`cause\` option when rethrowing the error.␊
    `

## Invalid #6
      1 | try {} catch ({}) { throw new Error('oops'); }

> Error 1/1

    `␊
    > 1 | try {} catch ({}) { throw new Error('oops'); }␊
        |        ^^^^^^^^^^^^^^^^^^^^^^^^^^^^^^^^^^^^^^^ Prefer specifying an old error as \`cause\` option when rethrowing the error.␊
    `

## Invalid #7
      1 | try {} catch ({error}) { throw new Error('oops'); }

> Error 1/1

    `␊
    > 1 | try {} catch ({error}) { throw new Error('oops'); }␊
        |        ^^^^^^^^^^^^^^^^^^^^^^^^^^^^^^^^^^^^^^^^^^^^ Prefer specifying an old error as \`cause\` option when rethrowing the error.␊
    `

## Invalid #8
      1 | try {} catch ({error}) { throw new Error('oops', {cause: error}); }

> Error 1/1

    `␊
    > 1 | try {} catch ({error}) { throw new Error('oops', {cause: error}); }␊
        |        ^^^^^^^^^^^^^^^^^^^^^^^^^^^^^^^^^^^^^^^^^^^^^^^^^^^^^^^^^^^^ Prefer specifying an old error as \`cause\` option when rethrowing the error.␊
    `

## Invalid #9
      1 | try {} catch {
      2 | 	const error = new Error('oops');
      3 | 	throw error;
      4 | }

> Error 1/1

    `␊
    > 1 | try {} catch {␊
        |        ^^^^^^^␊
    > 2 | 	const error = new Error('oops');␊
        | ^^^^^^^^^^^^^^^^^^^^^^^^^^^^^^^^^␊
    > 3 | 	throw error;␊
        | ^^^^^^^^^^^^^^^^^^^^^^^^^^^^^^^^^␊
    > 4 | }␊
        | ^^ Prefer specifying an old error as \`cause\` option when rethrowing the error.␊
    `

## Invalid #10
      1 | try {} catch (oldError) {
      2 | 	try {} catch {
      3 | 		throw oldError;
      4 | 	}
      5 | }

> Error 1/1

    `␊
      1 | try {} catch (oldError) {␊
    > 2 | 	try {} catch {␊
        | 	       ^^^^^^^␊
    > 3 | 		throw oldError;␊
        | ^^^^^^^^^^^^^^^^^␊
    > 4 | 	}␊
        | ^^^ Prefer specifying an old error as \`cause\` option when rethrowing the error.␊
      5 | }␊
    `

## Invalid #11
      1 | try {} catch { throw new Error('oops'); }

> Output

    `␊
      1 | try {} catch (error) { throw new Error('oops', {cause: error}); }␊
    `

> Error 1/1

    `␊
    > 1 | try {} catch { throw new Error('oops'); }␊
        |        ^^^^^^^^^^^^^^^^^^^^^^^^^^^^^^^^^^ Prefer specifying an old error as \`cause\` option when rethrowing the error.␊
    `

## Invalid #12
      1 | try {} catch (error) { throw new Error('oops'); }

> Output

    `␊
      1 | try {} catch (error) { throw new Error('oops', {cause: error}); }␊
    `

> Error 1/1

    `␊
    > 1 | try {} catch (error) { throw new Error('oops'); }␊
        |        ^^^^^^^^^^^^^^^^^^^^^^^^^^^^^^^^^^^^^^^^^^ Prefer specifying an old error as \`cause\` option when rethrowing the error.␊
    `

## Invalid #13
      1 | try {} catch (oldError) {
      2 | 	const error = new Error('oops');
      3 | 	throw error;
      4 | }

> Output

    `␊
      1 | try {} catch (oldError) {␊
      2 | 	const error = new Error('oops', {cause: oldError});␊
      3 | 	throw error;␊
      4 | }␊
    `

> Error 1/1

    `␊
    > 1 | try {} catch (oldError) {␊
        |        ^^^^^^^^^^^^^^^^^^␊
    > 2 | 	const error = new Error('oops');␊
        | ^^^^^^^^^^^^^^^^^^^^^^^^^^^^^^^^^␊
    > 3 | 	throw error;␊
        | ^^^^^^^^^^^^^^^^^^^^^^^^^^^^^^^^^␊
    > 4 | }␊
        | ^^ Prefer specifying an old error as \`cause\` option when rethrowing the error.␊
    `

## Invalid #14
      1 | try {} catch {
      2 | 	try {} catch (error) {
      3 | 		throw new Error(error);
      4 | 	}
      5 | }

> Output

    `␊
      1 | try {} catch {␊
      2 | 	try {} catch (error) {␊
      3 | 		throw new Error(error, {cause: error});␊
      4 | 	}␊
      5 | }␊
    `

> Error 1/1

    `␊
      1 | try {} catch {␊
    > 2 | 	try {} catch (error) {␊
        | 	       ^^^^^^^^^^^^^^^␊
    > 3 | 		throw new Error(error);␊
        | ^^^^^^^^^^^^^^^^^^^^^^^^^␊
    > 4 | 	}␊
        | ^^^ Prefer specifying an old error as \`cause\` option when rethrowing the error.␊
      5 | }␊
    `

## Invalid #15
      1 | try {} catch (error1) {
      2 | 	throw new Error(error1);
      3 | 	try {} catch (error2) {
      4 | 		throw new Error(error2);
      5 | 	}
      6 | }

> Output

    `␊
      1 | try {} catch (error1) {␊
      2 | 	throw new Error(error1, {cause: error1});␊
      3 | 	try {} catch (error2) {␊
      4 | 		throw new Error(error2, {cause: error2});␊
      5 | 	}␊
      6 | }␊
    `

> Error 1/2

    `␊
    > 1 | try {} catch (error1) {␊
        |        ^^^^^^^^^^^^^^^^␊
    > 2 | 	throw new Error(error1);␊
        | ^^^^^^^^^^^^^^^^^^^^^^^^^␊
    > 3 | 	try {} catch (error2) {␊
        | ^^^^^^^^^^^^^^^^^^^^^^^^^␊
    > 4 | 		throw new Error(error2);␊
        | ^^^^^^^^^^^^^^^^^^^^^^^^^␊
    > 5 | 	}␊
        | ^^^^^^^^^^^^^^^^^^^^^^^^^␊
    > 6 | }␊
        | ^^ Prefer specifying an old error as \`cause\` option when rethrowing the error.␊
    `

> Error 2/2

    `␊
      1 | try {} catch (error1) {␊
      2 | 	throw new Error(error1);␊
    > 3 | 	try {} catch (error2) {␊
        | 	       ^^^^^^^^^^^^^^^^␊
    > 4 | 		throw new Error(error2);␊
        | ^^^^^^^^^^^^^^^^^^^^^^^^^^␊
    > 5 | 	}␊
        | ^^^ Prefer specifying an old error as \`cause\` option when rethrowing the error.␊
      6 | }␊
    `

## Invalid #16
      1 | try {} catch {
      2 | 	try {} catch (error2) {
      3 | 		throw new Error(error1);
      4 | 	}
      5 | }

> Output

    `␊
      1 | try {} catch {␊
      2 | 	try {} catch (error2) {␊
      3 | 		throw new Error(error1, {cause: error2});␊
      4 | 	}␊
      5 | }␊
    `

> Error 1/1

    `␊
      1 | try {} catch {␊
    > 2 | 	try {} catch (error2) {␊
        | 	       ^^^^^^^^^^^^^^^^␊
    > 3 | 		throw new Error(error1);␊
        | ^^^^^^^^^^^^^^^^^^^^^^^^^^␊
    > 4 | 	}␊
        | ^^^ Prefer specifying an old error as \`cause\` option when rethrowing the error.␊
      5 | }␊
    `

## Invalid #17
      1 | try {} catch (error) {
      2 | 	if (true) {
      3 | 		throw new Error('oops', {cause: error});
      4 | 	} else if (true) {
      5 | 		throw new Error('oops');
      6 | 	} else {
      7 | 		throw new Error('oops');
      8 | 	}
      9 | }

> Output

    `␊
      1 | try {} catch (error) {␊
      2 | 	if (true) {␊
      3 | 		throw new Error('oops', {cause: error});␊
      4 | 	} else if (true) {␊
      5 | 		throw new Error('oops', {cause: error});␊
      6 | 	} else {␊
      7 | 		throw new Error('oops', {cause: error});␊
      8 | 	}␊
      9 | }␊
    `

> Error 1/2

    `␊
    > 1 | try {} catch (error) {␊
        |        ^^^^^^^^^^^^^^^␊
    > 2 | 	if (true) {␊
        | ^^^^^^^^^^^^␊
    > 3 | 		throw new Error('oops', {cause: error});␊
        | ^^^^^^^^^^^^␊
    > 4 | 	} else if (true) {␊
        | ^^^^^^^^^^^^␊
    > 5 | 		throw new Error('oops');␊
        | ^^^^^^^^^^^^␊
    > 6 | 	} else {␊
        | ^^^^^^^^^^^^␊
    > 7 | 		throw new Error('oops');␊
        | ^^^^^^^^^^^^␊
    > 8 | 	}␊
        | ^^^^^^^^^^^^␊
    > 9 | }␊
        | ^^ Prefer specifying an old error as \`cause\` option when rethrowing the error.␊
    `

> Error 2/2

    `␊
    > 1 | try {} catch (error) {␊
        |        ^^^^^^^^^^^^^^^␊
    > 2 | 	if (true) {␊
        | ^^^^^^^^^^^^␊
    > 3 | 		throw new Error('oops', {cause: error});␊
        | ^^^^^^^^^^^^␊
    > 4 | 	} else if (true) {␊
        | ^^^^^^^^^^^^␊
    > 5 | 		throw new Error('oops');␊
        | ^^^^^^^^^^^^␊
    > 6 | 	} else {␊
        | ^^^^^^^^^^^^␊
    > 7 | 		throw new Error('oops');␊
        | ^^^^^^^^^^^^␊
    > 8 | 	}␊
        | ^^^^^^^^^^^^␊
    > 9 | }␊
        | ^^ Prefer specifying an old error as \`cause\` option when rethrowing the error.␊
    `

## Invalid #18
      1 | try {} catch (error) {
      2 | 	if (true) {
      3 | 		if (true) {
      4 | 			throw new Error('oops', {cause: error});
      5 | 		} else {
      6 | 			throw new Error('oops');
      7 | 		}
      8 | 	}
      9 | }

> Output

    `␊
      1 | try {} catch (error) {␊
      2 | 	if (true) {␊
      3 | 		if (true) {␊
      4 | 			throw new Error('oops', {cause: error});␊
      5 | 		} else {␊
      6 | 			throw new Error('oops', {cause: error});␊
      7 | 		}␊
      8 | 	}␊
      9 | }␊
    `

> Error 1/1

    `␊
    > 1 | try {} catch (error) {␊
        |        ^^^^^^^^^^^^^^^␊
    > 2 | 	if (true) {␊
        | ^^^^^^^^^^^^␊
    > 3 | 		if (true) {␊
        | ^^^^^^^^^^^^␊
    > 4 | 			throw new Error('oops', {cause: error});␊
        | ^^^^^^^^^^^^␊
    > 5 | 		} else {␊
        | ^^^^^^^^^^^^␊
    > 6 | 			throw new Error('oops');␊
        | ^^^^^^^^^^^^␊
    > 7 | 		}␊
        | ^^^^^^^^^^^^␊
    > 8 | 	}␊
        | ^^^^^^^^^^^^␊
    > 9 | }␊
        | ^^ Prefer specifying an old error as \`cause\` option when rethrowing the error.␊
    `

## Invalid #19
      1 | try {} catch (error) {
      2 | 	let err;
      3 | 	err = new Error('oops');
      4 | 	throw err;
      5 | }

> Output

    `␊
      1 | try {} catch (error) {␊
      2 | 	let err;␊
      3 | 	err = new Error('oops', {cause: error});␊
      4 | 	throw err;␊
      5 | }␊
    `

> Error 1/1

    `␊
    > 1 | try {} catch (error) {␊
        |        ^^^^^^^^^^^^^^^␊
    > 2 | 	let err;␊
        | ^^^^^^^^^␊
    > 3 | 	err = new Error('oops');␊
        | ^^^^^^^^^␊
    > 4 | 	throw err;␊
        | ^^^^^^^^^␊
    > 5 | }␊
        | ^^ Prefer specifying an old error as \`cause\` option when rethrowing the error.␊
    `

## Invalid #20
      1 | try {} catch (error) {
      2 | 	let err;
      3 | 	if (1 + 1 >= 2) {
      4 | 		err = new Error('oops');
      5 | 	} else {
      6 | 		err = new Error('oops');
      7 | 	}
      8 | 	throw err;
      9 | }

> Output

    `␊
      1 | try {} catch (error) {␊
      2 | 	let err;␊
      3 | 	if (1 + 1 >= 2) {␊
      4 | 		err = new Error('oops', {cause: error});␊
      5 | 	} else {␊
      6 | 		err = new Error('oops', {cause: error});␊
      7 | 	}␊
      8 | 	throw err;␊
      9 | }␊
    `

> Error 1/2

    `␊
    > 1 | try {} catch (error) {␊
        |        ^^^^^^^^^^^^^^^␊
    > 2 | 	let err;␊
        | ^^^^^^^^^␊
    > 3 | 	if (1 + 1 >= 2) {␊
        | ^^^^^^^^^␊
    > 4 | 		err = new Error('oops');␊
        | ^^^^^^^^^␊
    > 5 | 	} else {␊
        | ^^^^^^^^^␊
    > 6 | 		err = new Error('oops');␊
        | ^^^^^^^^^␊
    > 7 | 	}␊
        | ^^^^^^^^^␊
    > 8 | 	throw err;␊
        | ^^^^^^^^^␊
    > 9 | }␊
        | ^^ Prefer specifying an old error as \`cause\` option when rethrowing the error.␊
    `

> Error 2/2

    `␊
    > 1 | try {} catch (error) {␊
        |        ^^^^^^^^^^^^^^^␊
    > 2 | 	let err;␊
        | ^^^^^^^^^␊
    > 3 | 	if (1 + 1 >= 2) {␊
        | ^^^^^^^^^␊
    > 4 | 		err = new Error('oops');␊
        | ^^^^^^^^^␊
    > 5 | 	} else {␊
        | ^^^^^^^^^␊
    > 6 | 		err = new Error('oops');␊
        | ^^^^^^^^^␊
    > 7 | 	}␊
        | ^^^^^^^^^␊
    > 8 | 	throw err;␊
        | ^^^^^^^^^␊
    > 9 | }␊
        | ^^ Prefer specifying an old error as \`cause\` option when rethrowing the error.␊
    `

## Invalid #21
      1 | try {} catch {
      2 | 	throw new Error('oops', {foo: 'bar'});
      3 | }

> Output

    `␊
      1 | try {} catch (error) {␊
      2 | 	throw new Error('oops', {foo: 'bar', cause: error});␊
      3 | }␊
    `

> Error 1/1

    `␊
    > 1 | try {} catch {␊
        |        ^^^^^^^␊
    > 2 | 	throw new Error('oops', {foo: 'bar'});␊
        | ^^^^^^^^^^^^^^^^^^^^^^^^^^^^^^^^^^^^^^^␊
    > 3 | }␊
        | ^^ Prefer specifying an old error as \`cause\` option when rethrowing the error.␊
    `

## Invalid #22
      1 | try {} catch (error) {
      2 | 	throw new CustomError('oops', {});
      3 | }

> Output

    `␊
      1 | try {} catch (error) {␊
      2 | 	throw new CustomError('oops', {cause: error});␊
      3 | }␊
    `

> Error 1/1

    `␊
    > 1 | try {} catch (error) {␊
        |        ^^^^^^^^^^^^^^^␊
    > 2 | 	throw new CustomError('oops', {});␊
        | ^^^^^^^^^^^^^^^^^^^^^^^^^^^^^^^^^^^␊
    > 3 | }␊
        | ^^ Prefer specifying an old error as \`cause\` option when rethrowing the error.␊
    `

## Invalid #23
      1 | try {} catch (error) {
      2 | 	throw new CustomError('oops', {foo});
      3 | }

> Output

    `␊
      1 | try {} catch (error) {␊
      2 | 	throw new CustomError('oops', {foo, cause: error});␊
      3 | }␊
    `

> Error 1/1

    `␊
    > 1 | try {} catch (error) {␊
        |        ^^^^^^^^^^^^^^^␊
    > 2 | 	throw new CustomError('oops', {foo});␊
        | ^^^^^^^^^^^^^^^^^^^^^^^^^^^^^^^^^^^^^^␊
    > 3 | }␊
        | ^^ Prefer specifying an old error as \`cause\` option when rethrowing the error.␊
    `

## Invalid #24
      1 | try {} catch (error) {
      2 | 	throw new CustomError('oops', {}, {});
      3 | }

> Output

    `␊
      1 | try {} catch (error) {␊
      2 | 	throw new CustomError('oops', {}, {cause: error});␊
      3 | }␊
    `

> Error 1/1

    `␊
    > 1 | try {} catch (error) {␊
        |        ^^^^^^^^^^^^^^^␊
    > 2 | 	throw new CustomError('oops', {}, {});␊
        | ^^^^^^^^^^^^^^^^^^^^^^^^^^^^^^^^^^^^^^^␊
    > 3 | }␊
        | ^^ Prefer specifying an old error as \`cause\` option when rethrowing the error.␊
    `

## Invalid #25
      1 | try {} catch (error) {
      2 | 	throw new CustomError('oops', {}, {foo});
      3 | }

> Output

    `␊
      1 | try {} catch (error) {␊
      2 | 	throw new CustomError('oops', {}, {foo, cause: error});␊
      3 | }␊
    `

> Error 1/1

    `␊
    > 1 | try {} catch (error) {␊
        |        ^^^^^^^^^^^^^^^␊
    > 2 | 	throw new CustomError('oops', {}, {foo});␊
        | ^^^^^^^^^^^^^^^^^^^^^^^^^^^^^^^^^^^^^^^^^^␊
    > 3 | }␊
        | ^^ Prefer specifying an old error as \`cause\` option when rethrowing the error.␊
    `

## Invalid #26
      1 | try {} catch (error) {
      2 | 	throw new CustomError('oops', {}, {foo: 'bar'});
      3 | }

> Output

    `␊
      1 | try {} catch (error) {␊
      2 | 	throw new CustomError('oops', {}, {foo: 'bar', cause: error});␊
      3 | }␊
    `

> Error 1/1

    `␊
    > 1 | try {} catch (error) {␊
        |        ^^^^^^^^^^^^^^^␊
    > 2 | 	throw new CustomError('oops', {}, {foo: 'bar'});␊
        | ^^^^^^^^^^^^^^^^^^^^^^^^^^^^^^^^^^^^^^^^^^^^^^^^^␊
    > 3 | }␊
        | ^^ Prefer specifying an old error as \`cause\` option when rethrowing the error.␊
    `

## Invalid #27
      1 | try {} catch (error) {
      2 | 	throw new CustomError('oops', {}, {foo: foo.bar});
      3 | }

> Output

    `␊
      1 | try {} catch (error) {␊
      2 | 	throw new CustomError('oops', {}, {foo: foo.bar, cause: error});␊
      3 | }␊
    `

> Error 1/1

    `␊
    > 1 | try {} catch (error) {␊
        |        ^^^^^^^^^^^^^^^␊
    > 2 | 	throw new CustomError('oops', {}, {foo: foo.bar});␊
        | ^^^^^^^^^^^^^^^^^^^^^^^^^^^^^^^^^^^^^^^^^^^^^^^^^^^␊
    > 3 | }␊
        | ^^ Prefer specifying an old error as \`cause\` option when rethrowing the error.␊
    `

## Invalid #1
      1 | promise.catch(error => { throw new Error; });

> Error 1/1

    `␊
    > 1 | promise.catch(error => { throw new Error; });␊
        | ^^^^^^^^^^^^^^^^^^^^^^^^^^^^^^^^^^^^^^^^^^^^ Prefer specifying an old error as \`cause\` option when rethrowing the error.␊
    `

## Invalid #2
      1 | promise.catch(function (error) { throw new Error; });

> Error 1/1

    `␊
    > 1 | promise.catch(function (error) { throw new Error; });␊
        | ^^^^^^^^^^^^^^^^^^^^^^^^^^^^^^^^^^^^^^^^^^^^^^^^^^^^ Prefer specifying an old error as \`cause\` option when rethrowing the error.␊
    `

## Invalid #3
      1 | promise.catch(error => { throw new Error(); });

> Error 1/1

    `␊
    > 1 | promise.catch(error => { throw new Error(); });␊
        | ^^^^^^^^^^^^^^^^^^^^^^^^^^^^^^^^^^^^^^^^^^^^^^ Prefer specifying an old error as \`cause\` option when rethrowing the error.␊
    `

## Invalid #4
      1 | promise.catch(function (error) { throw new Error(); });

> Error 1/1

    `␊
    > 1 | promise.catch(function (error) { throw new Error(); });␊
        | ^^^^^^^^^^^^^^^^^^^^^^^^^^^^^^^^^^^^^^^^^^^^^^^^^^^^^^ Prefer specifying an old error as \`cause\` option when rethrowing the error.␊
    `

## Invalid #5
      1 | promise.then(undefined, error => { throw new Error; });

> Error 1/1

    `␊
    > 1 | promise.then(undefined, error => { throw new Error; });␊
        | ^^^^^^^^^^^^^^^^^^^^^^^^^^^^^^^^^^^^^^^^^^^^^^^^^^^^^^ Prefer specifying an old error as \`cause\` option when rethrowing the error.␊
    `

## Invalid #6
      1 | promise.then(undefined, function (error) { throw new Error; });

> Error 1/1

    `␊
    > 1 | promise.then(undefined, function (error) { throw new Error; });␊
        | ^^^^^^^^^^^^^^^^^^^^^^^^^^^^^^^^^^^^^^^^^^^^^^^^^^^^^^^^^^^^^^ Prefer specifying an old error as \`cause\` option when rethrowing the error.␊
    `

## Invalid #7
      1 | promise.then(undefined, error => { throw new Error(); });

> Error 1/1

    `␊
    > 1 | promise.then(undefined, error => { throw new Error(); });␊
        | ^^^^^^^^^^^^^^^^^^^^^^^^^^^^^^^^^^^^^^^^^^^^^^^^^^^^^^^^ Prefer specifying an old error as \`cause\` option when rethrowing the error.␊
    `

## Invalid #8
      1 | promise.then(undefined, function (error) { throw new Error(); });

> Error 1/1

    `␊
    > 1 | promise.then(undefined, function (error) { throw new Error(); });␊
        | ^^^^^^^^^^^^^^^^^^^^^^^^^^^^^^^^^^^^^^^^^^^^^^^^^^^^^^^^^^^^^^^^ Prefer specifying an old error as \`cause\` option when rethrowing the error.␊
    `

## Invalid #9
      1 | promise.catch(function () {
      2 | 	let error = new Error;
      3 | 	throw error;
      4 | });

> Error 1/1

    `␊
    > 1 | promise.catch(function () {␊
        | ^^^^^^^^^^^^^^^^^^^^^^^^^^^␊
    > 2 | 	let error = new Error;␊
        | ^^^^^^^^^^^^^^^^^^^^^^^␊
    > 3 | 	throw error;␊
        | ^^^^^^^^^^^^^^^^^^^^^^^␊
    > 4 | });␊
        | ^^^ Prefer specifying an old error as \`cause\` option when rethrowing the error.␊
    `

## Invalid #10
      1 | promise.then(undefined, function () {
      2 | 	let error = new Error;
      3 | 	throw error;
      4 | });

> Error 1/1

    `␊
    > 1 | promise.then(undefined, function () {␊
        | ^^^^^^^^^^^^^^^^^^^^^^^^^^^^^^^^^^^^^␊
    > 2 | 	let error = new Error;␊
        | ^^^^^^^^^^^^^^^^^^^^^^^␊
    > 3 | 	throw error;␊
        | ^^^^^^^^^^^^^^^^^^^^^^^␊
    > 4 | });␊
        | ^^^ Prefer specifying an old error as \`cause\` option when rethrowing the error.␊
    `

## Invalid #11
      1 | promise.catch(({error}) => { throw new Error('oops', {cause: error}); });

> Error 1/1

    `␊
    > 1 | promise.catch(({error}) => { throw new Error('oops', {cause: error}); });␊
        | ^^^^^^^^^^^^^^^^^^^^^^^^^^^^^^^^^^^^^^^^^^^^^^^^^^^^^^^^^^^^^^^^^^^^^^^^ Prefer specifying an old error as \`cause\` option when rethrowing the error.␊
    `

## Invalid #12
      1 | promise.catch(function ({error}) { throw new Error('oops', {cause: error}); });

> Error 1/1

    `␊
    > 1 | promise.catch(function ({error}) { throw new Error('oops', {cause: error}); });␊
        | ^^^^^^^^^^^^^^^^^^^^^^^^^^^^^^^^^^^^^^^^^^^^^^^^^^^^^^^^^^^^^^^^^^^^^^^^^^^^^^ Prefer specifying an old error as \`cause\` option when rethrowing the error.␊
    `

## Invalid #13
      1 | let someCallback = ({}) => { throw new Error('oops'); };
      2 | promise.catch(someCallback);

> Error 1/1

    `␊
    > 1 | let someCallback = ({}) => { throw new Error('oops'); };␊
        |     ^^^^^^^^^^^^^^^^^^^^^^^^^^^^^^^^^^^^^^^^^^^^^^^^^^^ Prefer specifying an old error as \`cause\` option when rethrowing the error.␊
      2 | promise.catch(someCallback);␊
    `

## Invalid #14
      1 | promise.catch(({}) => { throw new Error('oops'); });

> Error 1/1

    `␊
    > 1 | promise.catch(({}) => { throw new Error('oops'); });␊
        | ^^^^^^^^^^^^^^^^^^^^^^^^^^^^^^^^^^^^^^^^^^^^^^^^^^^ Prefer specifying an old error as \`cause\` option when rethrowing the error.␊
    `

## Invalid #15
      1 | let someCallback = ({}) => { throw new Error('oops'); };
      2 | promise.then(undefined, someCallback);

> Error 1/1

    `␊
    > 1 | let someCallback = ({}) => { throw new Error('oops'); };␊
        |     ^^^^^^^^^^^^^^^^^^^^^^^^^^^^^^^^^^^^^^^^^^^^^^^^^^^ Prefer specifying an old error as \`cause\` option when rethrowing the error.␊
      2 | promise.then(undefined, someCallback);␊
    `

## Invalid #16
      1 | promise.then(undefined, ({}) => { throw new Error('oops'); });;

> Error 1/1

    `␊
    > 1 | promise.then(undefined, ({}) => { throw new Error('oops'); });;␊
        | ^^^^^^^^^^^^^^^^^^^^^^^^^^^^^^^^^^^^^^^^^^^^^^^^^^^^^^^^^^^^^ Prefer specifying an old error as \`cause\` option when rethrowing the error.␊
    `

## Invalid #17
      1 | try {
      2 |
      3 | } catch (error) {
      4 | 	promise.catch(() => {
      5 | 		throw new Error('oops');
      6 | 	});
      7 | }

> Output

    `␊
      1 | try {␊
      2 |␊
      3 | } catch (error) {␊
      4 | 	promise.catch((error) => {␊
      5 | 		throw new Error('oops', {cause: error});␊
      6 | 	});␊
      7 | }␊
    `

> Error 1/1

    `␊
      1 | try {␊
      2 |␊
      3 | } catch (error) {␊
    > 4 | 	promise.catch(() => {␊
        | 	^^^^^^^^^^^^^^^^^^^^^␊
    > 5 | 		throw new Error('oops');␊
        | ^^^^^^^^^^^^^^^^^^^^^^^^^^␊
    > 6 | 	});␊
        | ^^^^ Prefer specifying an old error as \`cause\` option when rethrowing the error.␊
      7 | }␊
    `

## Invalid #18
      1 | promise.catch(error => { throw new Error('oops'); });

> Output

    `␊
      1 | promise.catch(error => { throw new Error('oops', {cause: error}); });␊
    `

> Error 1/1

    `␊
    > 1 | promise.catch(error => { throw new Error('oops'); });␊
        | ^^^^^^^^^^^^^^^^^^^^^^^^^^^^^^^^^^^^^^^^^^^^^^^^^^^^ Prefer specifying an old error as \`cause\` option when rethrowing the error.␊
    `

## Invalid #19
      1 | promise.catch(function (error) { throw new Error('oops'); });

> Output

    `␊
      1 | promise.catch(function (error) { throw new Error('oops', {cause: error}); });␊
    `

> Error 1/1

    `␊
    > 1 | promise.catch(function (error) { throw new Error('oops'); });␊
        | ^^^^^^^^^^^^^^^^^^^^^^^^^^^^^^^^^^^^^^^^^^^^^^^^^^^^^^^^^^^^ Prefer specifying an old error as \`cause\` option when rethrowing the error.␊
    `

## Invalid #20
      1 | promise.then(undefined, error => { throw new Error('oops'); });

> Output

    `␊
      1 | promise.then(undefined, error => { throw new Error('oops', {cause: error}); });␊
    `

> Error 1/1

    `␊
    > 1 | promise.then(undefined, error => { throw new Error('oops'); });␊
        | ^^^^^^^^^^^^^^^^^^^^^^^^^^^^^^^^^^^^^^^^^^^^^^^^^^^^^^^^^^^^^^ Prefer specifying an old error as \`cause\` option when rethrowing the error.␊
    `

## Invalid #21
      1 | promise.then(undefined, function (error) { throw new Error('oops'); });

> Output

    `␊
      1 | promise.then(undefined, function (error) { throw new Error('oops', {cause: error}); });␊
    `

> Error 1/1

    `␊
    > 1 | promise.then(undefined, function (error) { throw new Error('oops'); });␊
        | ^^^^^^^^^^^^^^^^^^^^^^^^^^^^^^^^^^^^^^^^^^^^^^^^^^^^^^^^^^^^^^^^^^^^^^ Prefer specifying an old error as \`cause\` option when rethrowing the error.␊
    `

## Invalid #22
      1 | promise.catch(oldError => {
      2 | 	const error = new Error('oops', {foo: 'bar'});
      3 | 	throw error;
      4 | });

> Output

    `␊
      1 | promise.catch(oldError => {␊
      2 | 	const error = new Error('oops', {foo: 'bar', cause: oldError});␊
      3 | 	throw error;␊
      4 | });␊
    `

> Error 1/1

    `␊
    > 1 | promise.catch(oldError => {␊
        | ^^^^^^^^^^^^^^^^^^^^^^^^^^^␊
    > 2 | 	const error = new Error('oops', {foo: 'bar'});␊
        | ^^^^^^^^^^^^^^^^^^^^^^^^^^^^^^^^^^^^^^^^^^^^^^^␊
    > 3 | 	throw error;␊
        | ^^^^^^^^^^^^^^^^^^^^^^^^^^^^^^^^^^^^^^^^^^^^^^^␊
    > 4 | });␊
        | ^^^ Prefer specifying an old error as \`cause\` option when rethrowing the error.␊
    `

## Invalid #23
      1 | promise.catch(function (oldError) {
      2 | 	const error = new Error('oops', {foo: 'bar'});
      3 | 	throw error;
      4 | });

> Output

    `␊
      1 | promise.catch(function (oldError) {␊
      2 | 	const error = new Error('oops', {foo: 'bar', cause: oldError});␊
      3 | 	throw error;␊
      4 | });␊
    `

> Error 1/1

    `␊
    > 1 | promise.catch(function (oldError) {␊
        | ^^^^^^^^^^^^^^^^^^^^^^^^^^^^^^^^^^^␊
    > 2 | 	const error = new Error('oops', {foo: 'bar'});␊
        | ^^^^^^^^^^^^^^^^^^^^^^^^^^^^^^^^^^^^^^^^^^^^^^^␊
    > 3 | 	throw error;␊
        | ^^^^^^^^^^^^^^^^^^^^^^^^^^^^^^^^^^^^^^^^^^^^^^^␊
    > 4 | });␊
        | ^^^ Prefer specifying an old error as \`cause\` option when rethrowing the error.␊
    `

## Invalid #24
      1 | promise.then(undefined, oldError => {
      2 | 	const error = new Error('oops', {foo: 'bar'});
      3 | 	throw error;
      4 | });

> Output

    `␊
      1 | promise.then(undefined, oldError => {␊
      2 | 	const error = new Error('oops', {foo: 'bar', cause: oldError});␊
      3 | 	throw error;␊
      4 | });␊
    `

> Error 1/1

    `␊
    > 1 | promise.then(undefined, oldError => {␊
        | ^^^^^^^^^^^^^^^^^^^^^^^^^^^^^^^^^^^^^␊
    > 2 | 	const error = new Error('oops', {foo: 'bar'});␊
        | ^^^^^^^^^^^^^^^^^^^^^^^^^^^^^^^^^^^^^^^^^^^^^^^␊
    > 3 | 	throw error;␊
        | ^^^^^^^^^^^^^^^^^^^^^^^^^^^^^^^^^^^^^^^^^^^^^^^␊
    > 4 | });␊
        | ^^^ Prefer specifying an old error as \`cause\` option when rethrowing the error.␊
    `

## Invalid #25
      1 | promise.then(undefined, function (oldError) {
      2 | 	const error = new Error('oops', {foo: 'bar'});
      3 | 	throw error;
      4 | });

> Output

    `␊
      1 | promise.then(undefined, function (oldError) {␊
      2 | 	const error = new Error('oops', {foo: 'bar', cause: oldError});␊
      3 | 	throw error;␊
      4 | });␊
    `

> Error 1/1

    `␊
    > 1 | promise.then(undefined, function (oldError) {␊
        | ^^^^^^^^^^^^^^^^^^^^^^^^^^^^^^^^^^^^^^^^^^^^^␊
    > 2 | 	const error = new Error('oops', {foo: 'bar'});␊
        | ^^^^^^^^^^^^^^^^^^^^^^^^^^^^^^^^^^^^^^^^^^^^^^^␊
    > 3 | 	throw error;␊
        | ^^^^^^^^^^^^^^^^^^^^^^^^^^^^^^^^^^^^^^^^^^^^^^^␊
    > 4 | });␊
        | ^^^ Prefer specifying an old error as \`cause\` option when rethrowing the error.␊
    `

## Invalid #26
      1 | promise.catch(error => {
      2 | 	if (true) {
      3 | 		throw new Error('oops', {cause: error});
      4 | 	} else if (true) {
      5 | 		throw new Error('oops');
      6 | 	} else {
      7 | 		throw new Error('oops');
      8 | 	}
      9 | });

> Output

    `␊
      1 | promise.catch(error => {␊
      2 | 	if (true) {␊
      3 | 		throw new Error('oops', {cause: error});␊
      4 | 	} else if (true) {␊
      5 | 		throw new Error('oops', {cause: error});␊
      6 | 	} else {␊
      7 | 		throw new Error('oops', {cause: error});␊
      8 | 	}␊
      9 | });␊
    `

> Error 1/2

    `␊
    > 1 | promise.catch(error => {␊
        | ^^^^^^^^^^^^^^^^^^^^^^^^␊
    > 2 | 	if (true) {␊
        | ^^^^^^^^^^^^␊
    > 3 | 		throw new Error('oops', {cause: error});␊
        | ^^^^^^^^^^^^␊
    > 4 | 	} else if (true) {␊
        | ^^^^^^^^^^^^␊
    > 5 | 		throw new Error('oops');␊
        | ^^^^^^^^^^^^␊
    > 6 | 	} else {␊
        | ^^^^^^^^^^^^␊
    > 7 | 		throw new Error('oops');␊
        | ^^^^^^^^^^^^␊
    > 8 | 	}␊
        | ^^^^^^^^^^^^␊
    > 9 | });␊
        | ^^^ Prefer specifying an old error as \`cause\` option when rethrowing the error.␊
    `

> Error 2/2

    `␊
    > 1 | promise.catch(error => {␊
        | ^^^^^^^^^^^^^^^^^^^^^^^^␊
    > 2 | 	if (true) {␊
        | ^^^^^^^^^^^^␊
    > 3 | 		throw new Error('oops', {cause: error});␊
        | ^^^^^^^^^^^^␊
    > 4 | 	} else if (true) {␊
        | ^^^^^^^^^^^^␊
    > 5 | 		throw new Error('oops');␊
        | ^^^^^^^^^^^^␊
    > 6 | 	} else {␊
        | ^^^^^^^^^^^^␊
    > 7 | 		throw new Error('oops');␊
        | ^^^^^^^^^^^^␊
    > 8 | 	}␊
        | ^^^^^^^^^^^^␊
    > 9 | });␊
        | ^^^ Prefer specifying an old error as \`cause\` option when rethrowing the error.␊
    `

## Invalid #27
      1 | promise.catch(error => {
      2 | 	if (true) {
      3 | 		if (true) {
      4 | 			throw new Error('oops', {cause: error});
      5 | 		} else {
      6 | 			throw new Error('oops');
      7 | 		}
      8 | 	}
      9 | });

> Output

    `␊
      1 | promise.catch(error => {␊
      2 | 	if (true) {␊
      3 | 		if (true) {␊
      4 | 			throw new Error('oops', {cause: error});␊
      5 | 		} else {␊
      6 | 			throw new Error('oops', {cause: error});␊
      7 | 		}␊
      8 | 	}␊
      9 | });␊
    `

> Error 1/1

    `␊
    > 1 | promise.catch(error => {␊
        | ^^^^^^^^^^^^^^^^^^^^^^^^␊
    > 2 | 	if (true) {␊
        | ^^^^^^^^^^^^␊
    > 3 | 		if (true) {␊
        | ^^^^^^^^^^^^␊
    > 4 | 			throw new Error('oops', {cause: error});␊
        | ^^^^^^^^^^^^␊
    > 5 | 		} else {␊
        | ^^^^^^^^^^^^␊
    > 6 | 			throw new Error('oops');␊
        | ^^^^^^^^^^^^␊
    > 7 | 		}␊
        | ^^^^^^^^^^^^␊
    > 8 | 	}␊
        | ^^^^^^^^^^^^␊
    > 9 | });␊
        | ^^^ Prefer specifying an old error as \`cause\` option when rethrowing the error.␊
    `

## Invalid #28
      1 | promise.then(undefined, error => {
      2 | 	if (true) {
      3 | 		throw new Error('oops', {cause: error});
      4 | 	} else if (true) {
      5 | 		throw new Error('oops');
      6 | 	} else {
      7 | 		throw new Error('oops');
      8 | 	}
      9 | });

> Output

    `␊
      1 | promise.then(undefined, error => {␊
      2 | 	if (true) {␊
      3 | 		throw new Error('oops', {cause: error});␊
      4 | 	} else if (true) {␊
      5 | 		throw new Error('oops', {cause: error});␊
      6 | 	} else {␊
      7 | 		throw new Error('oops', {cause: error});␊
      8 | 	}␊
      9 | });␊
    `

> Error 1/2

    `␊
    > 1 | promise.then(undefined, error => {␊
        | ^^^^^^^^^^^^^^^^^^^^^^^^^^^^^^^^^^␊
    > 2 | 	if (true) {␊
        | ^^^^^^^^^^^^␊
    > 3 | 		throw new Error('oops', {cause: error});␊
        | ^^^^^^^^^^^^␊
    > 4 | 	} else if (true) {␊
        | ^^^^^^^^^^^^␊
    > 5 | 		throw new Error('oops');␊
        | ^^^^^^^^^^^^␊
    > 6 | 	} else {␊
        | ^^^^^^^^^^^^␊
    > 7 | 		throw new Error('oops');␊
        | ^^^^^^^^^^^^␊
    > 8 | 	}␊
        | ^^^^^^^^^^^^␊
    > 9 | });␊
        | ^^^ Prefer specifying an old error as \`cause\` option when rethrowing the error.␊
    `

> Error 2/2

    `␊
    > 1 | promise.then(undefined, error => {␊
        | ^^^^^^^^^^^^^^^^^^^^^^^^^^^^^^^^^^␊
    > 2 | 	if (true) {␊
        | ^^^^^^^^^^^^␊
    > 3 | 		throw new Error('oops', {cause: error});␊
        | ^^^^^^^^^^^^␊
    > 4 | 	} else if (true) {␊
        | ^^^^^^^^^^^^␊
    > 5 | 		throw new Error('oops');␊
        | ^^^^^^^^^^^^␊
    > 6 | 	} else {␊
        | ^^^^^^^^^^^^␊
    > 7 | 		throw new Error('oops');␊
        | ^^^^^^^^^^^^␊
    > 8 | 	}␊
        | ^^^^^^^^^^^^␊
    > 9 | });␊
        | ^^^ Prefer specifying an old error as \`cause\` option when rethrowing the error.␊
    `

## Invalid #29
      1 | promise.then(undefined, error => {
      2 | 	if (true) {
      3 | 		if (true) {
      4 | 			throw new Error('oops', {cause: error});
      5 | 		} else {
      6 | 			throw new Error('oops');
      7 | 		}
      8 | 	}
      9 | });

> Output

    `␊
      1 | promise.then(undefined, error => {␊
      2 | 	if (true) {␊
      3 | 		if (true) {␊
      4 | 			throw new Error('oops', {cause: error});␊
      5 | 		} else {␊
      6 | 			throw new Error('oops', {cause: error});␊
      7 | 		}␊
      8 | 	}␊
      9 | });␊
    `

> Error 1/1

    `␊
    > 1 | promise.then(undefined, error => {␊
        | ^^^^^^^^^^^^^^^^^^^^^^^^^^^^^^^^^^␊
    > 2 | 	if (true) {␊
        | ^^^^^^^^^^^^␊
    > 3 | 		if (true) {␊
        | ^^^^^^^^^^^^␊
    > 4 | 			throw new Error('oops', {cause: error});␊
        | ^^^^^^^^^^^^␊
    > 5 | 		} else {␊
        | ^^^^^^^^^^^^␊
    > 6 | 			throw new Error('oops');␊
        | ^^^^^^^^^^^^␊
    > 7 | 		}␊
        | ^^^^^^^^^^^^␊
    > 8 | 	}␊
        | ^^^^^^^^^^^^␊
    > 9 | });␊
        | ^^^ Prefer specifying an old error as \`cause\` option when rethrowing the error.␊
    `

## Invalid #30
      1 | try {} catch (error1) {
      2 | 	foo(bar).catch(error2 => {
      3 | 		throw new Error('oops');
      4 | 	})
      5 |
      6 | 	function foo(bar) {
      7 | 		throw new Error('oops');
      8 | 	}
      9 | }

> Output

    `␊
      1 | try {} catch (error1) {␊
      2 | 	foo(bar).catch(error2 => {␊
      3 | 		throw new Error('oops', {cause: error2});␊
      4 | 	})␊
      5 |␊
      6 | 	function foo(bar) {␊
      7 | 		throw new Error('oops');␊
      8 | 	}␊
      9 | }␊
    `

> Error 1/1

    `␊
      1 | try {} catch (error1) {␊
    > 2 | 	foo(bar).catch(error2 => {␊
        | 	^^^^^^^^^^^^^^^^^^^^^^^^^^␊
    > 3 | 		throw new Error('oops');␊
        | ^^^^^^^^^^^^^^^^^^^^^^^^^^␊
    > 4 | 	})␊
        | ^^^^ Prefer specifying an old error as \`cause\` option when rethrowing the error.␊
      5 |␊
      6 | 	function foo(bar) {␊
      7 | 		throw new Error('oops');␊
      8 | 	}␊
      9 | }␊
    `

## Invalid #31
      1 | const someCallback = error => {
      2 | 	throw new Error('oops');
      3 | };
      4 |
      5 | promise.catch(someCallback);

> Output

    `␊
      1 | const someCallback = error => {␊
      2 | 	throw new Error('oops', {cause: error});␊
      3 | };␊
      4 |␊
      5 | promise.catch(someCallback);␊
    `

> Error 1/1

    `␊
    > 1 | const someCallback = error => {␊
        |       ^^^^^^^^^^^^^^^^^^^^^^^^^␊
    > 2 | 	throw new Error('oops');␊
        | ^^^^^^^^^^^^^^^^^^^^^^^^^␊
    > 3 | };␊
        | ^^ Prefer specifying an old error as \`cause\` option when rethrowing the error.␊
      4 |␊
      5 | promise.catch(someCallback);␊
    `

## Invalid #32
      1 | const someCallback = function (error) {
      2 | 	throw new Error('oops');
      3 | };
      4 |
      5 | promise.catch(someCallback);

> Output

    `␊
      1 | const someCallback = function (error) {␊
      2 | 	throw new Error('oops', {cause: error});␊
      3 | };␊
      4 |␊
      5 | promise.catch(someCallback);␊
    `

> Error 1/1

    `␊
    > 1 | const someCallback = function (error) {␊
        |       ^^^^^^^^^^^^^^^^^^^^^^^^^^^^^^^^^␊
    > 2 | 	throw new Error('oops');␊
        | ^^^^^^^^^^^^^^^^^^^^^^^^^␊
    > 3 | };␊
        | ^^ Prefer specifying an old error as \`cause\` option when rethrowing the error.␊
      4 |␊
      5 | promise.catch(someCallback);␊
    `

## Invalid #33
      1 | const someCallback = function (error) {
      2 | 	throw new Error('oops');
      3 | };
      4 |
      5 | promise.catch(err => someCallback(err));

> Output

    `␊
      1 | const someCallback = function (error) {␊
      2 | 	throw new Error('oops', {cause: error});␊
      3 | };␊
      4 |␊
      5 | promise.catch(err => someCallback(err));␊
    `

> Error 1/1

    `␊
    > 1 | const someCallback = function (error) {␊
        |       ^^^^^^^^^^^^^^^^^^^^^^^^^^^^^^^^^␊
    > 2 | 	throw new Error('oops');␊
        | ^^^^^^^^^^^^^^^^^^^^^^^^^␊
    > 3 | };␊
        | ^^ Prefer specifying an old error as \`cause\` option when rethrowing the error.␊
      4 |␊
      5 | promise.catch(err => someCallback(err));␊
    `

## Invalid #34
      1 | const someCallback = error => {
      2 | 	throw new Error('oops');
      3 | };
      4 |
      5 | promise.then(undefined, someCallback);

> Output

    `␊
      1 | const someCallback = error => {␊
      2 | 	throw new Error('oops', {cause: error});␊
      3 | };␊
      4 |␊
      5 | promise.then(undefined, someCallback);␊
    `

> Error 1/1

    `␊
    > 1 | const someCallback = error => {␊
        |       ^^^^^^^^^^^^^^^^^^^^^^^^^␊
    > 2 | 	throw new Error('oops');␊
        | ^^^^^^^^^^^^^^^^^^^^^^^^^␊
    > 3 | };␊
        | ^^ Prefer specifying an old error as \`cause\` option when rethrowing the error.␊
      4 |␊
      5 | promise.then(undefined, someCallback);␊
    `

## Invalid #35
      1 | const someCallback = function (error) {
      2 | 	throw new Error('oops');
      3 | };
      4 |
      5 | promise.then(undefined, someCallback);

> Output

    `␊
      1 | const someCallback = function (error) {␊
      2 | 	throw new Error('oops', {cause: error});␊
      3 | };␊
      4 |␊
      5 | promise.then(undefined, someCallback);␊
    `

> Error 1/1

    `␊
    > 1 | const someCallback = function (error) {␊
        |       ^^^^^^^^^^^^^^^^^^^^^^^^^^^^^^^^^␊
    > 2 | 	throw new Error('oops');␊
        | ^^^^^^^^^^^^^^^^^^^^^^^^^␊
    > 3 | };␊
        | ^^ Prefer specifying an old error as \`cause\` option when rethrowing the error.␊
      4 |␊
      5 | promise.then(undefined, someCallback);␊
    `

## Invalid #36
      1 | const someCallback = function (error) {
      2 | 	throw new Error('oops');
      3 | };
      4 |
      5 | promise.then(undefined, err => someCallback(err));

> Output

    `␊
      1 | const someCallback = function (error) {␊
      2 | 	throw new Error('oops', {cause: error});␊
      3 | };␊
      4 |␊
      5 | promise.then(undefined, err => someCallback(err));␊
    `

> Error 1/1

    `␊
    > 1 | const someCallback = function (error) {␊
        |       ^^^^^^^^^^^^^^^^^^^^^^^^^^^^^^^^^␊
    > 2 | 	throw new Error('oops');␊
        | ^^^^^^^^^^^^^^^^^^^^^^^^^␊
    > 3 | };␊
        | ^^ Prefer specifying an old error as \`cause\` option when rethrowing the error.␊
      4 |␊
      5 | promise.then(undefined, err => someCallback(err));␊
    `

## Invalid #37
       1 | let someCallback = fooError => {
       2 | 	throw new Error('foo');
       3 | };
       4 |
       5 | try {
       6 |
       7 | } catch (barError) {
       8 | 	someCallback = barError => {
       9 | 		throw new Error('bar');
      10 | 	}
      11 | }
      12 |
      13 | {
      14 | 	promise.catch(someCallback);
      15 | }

> Output

    `␊
       1 | let someCallback = fooError => {␊
       2 | 	throw new Error('foo', {cause: fooError});␊
       3 | };␊
       4 |␊
       5 | try {␊
       6 |␊
       7 | } catch (barError) {␊
       8 | 	someCallback = barError => {␊
       9 | 		throw new Error('bar', {cause: barError});␊
      10 | 	}␊
      11 | }␊
      12 |␊
      13 | {␊
      14 | 	promise.catch(someCallback);␊
      15 | }␊
    `

> Error 1/2

    `␊
    >  1 | let someCallback = fooError => {␊
         |     ^^^^^^^^^^^^^^^^^^^^^^^^^^^^␊
    >  2 | 	throw new Error('foo');␊
         | ^^^^^^^^^^^^^^^^^^^^^^^^␊
    >  3 | };␊
         | ^^ Prefer specifying an old error as \`cause\` option when rethrowing the error.␊
       4 |␊
       5 | try {␊
       6 |␊
       7 | } catch (barError) {␊
       8 | 	someCallback = barError => {␊
       9 | 		throw new Error('bar');␊
      10 | 	}␊
      11 | }␊
      12 |␊
      13 | {␊
      14 | 	promise.catch(someCallback);␊
      15 | }␊
    `

> Error 2/2

    `␊
       1 | let someCallback = fooError => {␊
       2 | 	throw new Error('foo');␊
       3 | };␊
       4 |␊
       5 | try {␊
       6 |␊
       7 | } catch (barError) {␊
    >  8 | 	someCallback = barError => {␊
         | 	^^^^^^^^^^^^^^^^^^^^^^^^^^^^␊
    >  9 | 		throw new Error('bar');␊
         | ^^^^^^^^^^^^^^^^^^^^^^^^^␊
    > 10 | 	}␊
         | ^^^ Prefer specifying an old error as \`cause\` option when rethrowing the error.␊
      11 | }␊
      12 |␊
      13 | {␊
      14 | 	promise.catch(someCallback);␊
      15 | }␊
    `

## Invalid #38
      1 | promise.catch(() => { throw new Error('oops'); });

> Output

    `␊
      1 | promise.catch((error) => { throw new Error('oops', {cause: error}); });␊
    `

> Error 1/1

    `␊
    > 1 | promise.catch(() => { throw new Error('oops'); });␊
        | ^^^^^^^^^^^^^^^^^^^^^^^^^^^^^^^^^^^^^^^^^^^^^^^^^ Prefer specifying an old error as \`cause\` option when rethrowing the error.␊
    `

## Invalid #39
      1 | promise.catch(function () { throw new Error('oops'); });

> Output

    `␊
      1 | promise.catch(function (error) { throw new Error('oops', {cause: error}); });␊
    `

> Error 1/1

    `␊
    > 1 | promise.catch(function () { throw new Error('oops'); });␊
        | ^^^^^^^^^^^^^^^^^^^^^^^^^^^^^^^^^^^^^^^^^^^^^^^^^^^^^^^ Prefer specifying an old error as \`cause\` option when rethrowing the error.␊
    `

## Invalid #40
      1 | promise.then(undefined, function () { throw new Error('oops'); });

> Output

    `␊
      1 | promise.then(undefined, function (error) { throw new Error('oops', {cause: error}); });␊
    `

> Error 1/1

    `␊
    > 1 | promise.then(undefined, function () { throw new Error('oops'); });␊
        | ^^^^^^^^^^^^^^^^^^^^^^^^^^^^^^^^^^^^^^^^^^^^^^^^^^^^^^^^^^^^^^^^^ Prefer specifying an old error as \`cause\` option when rethrowing the error.␊
    `

## Invalid #41
      1 | promise.then(undefined, () => { throw new Error('oops'); });

> Output

    `␊
      1 | promise.then(undefined, (error) => { throw new Error('oops', {cause: error}); });␊
    `

> Error 1/1

    `␊
    > 1 | promise.then(undefined, () => { throw new Error('oops'); });␊
        | ^^^^^^^^^^^^^^^^^^^^^^^^^^^^^^^^^^^^^^^^^^^^^^^^^^^^^^^^^^^ Prefer specifying an old error as \`cause\` option when rethrowing the error.␊
    `

## Invalid #42
      1 | promise.catch(function () {
      2 | 	let error;
      3 | 	error = new Error('oops');
      4 | 	throw error;
      5 | });

> Error 1/1

    `␊
    > 1 | promise.catch(function () {␊
        | ^^^^^^^^^^^^^^^^^^^^^^^^^^^␊
    > 2 | 	let error;␊
        | ^^^^^^^^^^^␊
    > 3 | 	error = new Error('oops');␊
        | ^^^^^^^^^^^␊
    > 4 | 	throw error;␊
        | ^^^^^^^^^^^␊
    > 5 | });␊
        | ^^^ Prefer specifying an old error as \`cause\` option when rethrowing the error.␊
    `

## Invalid #43
       1 | promise.catch(function () {
       2 | 	let error;
       3 |
       4 | 	if (someCondition) {
       5 | 		error = new Error('oops');
       6 | 	} else {
       7 | 		error = new Error('oops');
       8 | 	}
       9 | 	throw error;
      10 | });

> Error 1/2

    `␊
    >  1 | promise.catch(function () {␊
         | ^^^^^^^^^^^^^^^^^^^^^^^^^^^␊
    >  2 | 	let error;␊
         | ^^^^^^^^^^^␊
    >  3 |␊
         | ^^^^^^^^^^^␊
    >  4 | 	if (someCondition) {␊
         | ^^^^^^^^^^^␊
    >  5 | 		error = new Error('oops');␊
         | ^^^^^^^^^^^␊
    >  6 | 	} else {␊
         | ^^^^^^^^^^^␊
    >  7 | 		error = new Error('oops');␊
         | ^^^^^^^^^^^␊
    >  8 | 	}␊
         | ^^^^^^^^^^^␊
    >  9 | 	throw error;␊
         | ^^^^^^^^^^^␊
    > 10 | });␊
         | ^^^ Prefer specifying an old error as \`cause\` option when rethrowing the error.␊
    `

> Error 2/2

    `␊
    >  1 | promise.catch(function () {␊
         | ^^^^^^^^^^^^^^^^^^^^^^^^^^^␊
    >  2 | 	let error;␊
         | ^^^^^^^^^^^␊
    >  3 |␊
         | ^^^^^^^^^^^␊
    >  4 | 	if (someCondition) {␊
         | ^^^^^^^^^^^␊
    >  5 | 		error = new Error('oops');␊
         | ^^^^^^^^^^^␊
    >  6 | 	} else {␊
         | ^^^^^^^^^^^␊
    >  7 | 		error = new Error('oops');␊
         | ^^^^^^^^^^^␊
    >  8 | 	}␊
         | ^^^^^^^^^^^␊
    >  9 | 	throw error;␊
         | ^^^^^^^^^^^␊
    > 10 | });␊
         | ^^^ Prefer specifying an old error as \`cause\` option when rethrowing the error.␊
    `

## Invalid #44
      1 | asyncFunction().catch(() => {
      2 | 	return promise.catch(() => {
      3 | 		throw new Error('oops');
      4 | 	});
      5 | });

> Output

    `␊
      1 | asyncFunction().catch(() => {␊
      2 | 	return promise.catch((error) => {␊
      3 | 		throw new Error('oops', {cause: error});␊
      4 | 	});␊
      5 | });␊
    `

> Error 1/1

    `␊
      1 | asyncFunction().catch(() => {␊
    > 2 | 	return promise.catch(() => {␊
        | 	       ^^^^^^^^^^^^^^^^^^^^^␊
    > 3 | 		throw new Error('oops');␊
        | ^^^^^^^^^^^^^^^^^^^^^^^^^^␊
    > 4 | 	});␊
        | ^^^^ Prefer specifying an old error as \`cause\` option when rethrowing the error.␊
      5 | });␊
    `

## Invalid #45
      1 | asyncFunction().catch(function () {
      2 | 	return promise.catch(function () {
      3 | 		throw new Error('oops');
      4 | 	});
      5 | });

> Output

    `␊
      1 | asyncFunction().catch(function () {␊
      2 | 	return promise.catch(function (error) {␊
      3 | 		throw new Error('oops', {cause: error});␊
      4 | 	});␊
      5 | });␊
    `

> Error 1/1

    `␊
      1 | asyncFunction().catch(function () {␊
    > 2 | 	return promise.catch(function () {␊
        | 	       ^^^^^^^^^^^^^^^^^^^^^^^^^^^␊
    > 3 | 		throw new Error('oops');␊
        | ^^^^^^^^^^^^^^^^^^^^^^^^^^␊
    > 4 | 	});␊
        | ^^^^ Prefer specifying an old error as \`cause\` option when rethrowing the error.␊
      5 | });␊
    `

## Invalid #46
      1 | promise1.catch(() => {
      2 | 	return promise2.catch(() => {
      3 | 		throw new Error('oops');
      4 | 	});
      5 | })
      6 | .catch(onError);

> Output

    `␊
      1 | promise1.catch(() => {␊
      2 | 	return promise2.catch((error) => {␊
      3 | 		throw new Error('oops', {cause: error});␊
      4 | 	});␊
      5 | })␊
      6 | .catch(onError);␊
    `

> Error 1/1

    `␊
      1 | promise1.catch(() => {␊
    > 2 | 	return promise2.catch(() => {␊
        | 	       ^^^^^^^^^^^^^^^^^^^^^^␊
    > 3 | 		throw new Error('oops');␊
        | ^^^^^^^^^^^^^^^^^^^^^^^^^^␊
    > 4 | 	});␊
        | ^^^^ Prefer specifying an old error as \`cause\` option when rethrowing the error.␊
      5 | })␊
      6 | .catch(onError);␊
    `

## Invalid #47
      1 | promise1.catch(function () {
      2 | 	return promise2.catch(function () {
      3 | 		throw new Error('oops');
      4 | 	});
      5 | })
      6 | .catch(onError);

> Output

    `␊
      1 | promise1.catch(function () {␊
      2 | 	return promise2.catch(function (error) {␊
      3 | 		throw new Error('oops', {cause: error});␊
      4 | 	});␊
      5 | })␊
      6 | .catch(onError);␊
    `

> Error 1/1

    `␊
      1 | promise1.catch(function () {␊
    > 2 | 	return promise2.catch(function () {␊
        | 	       ^^^^^^^^^^^^^^^^^^^^^^^^^^^^␊
    > 3 | 		throw new Error('oops');␊
        | ^^^^^^^^^^^^^^^^^^^^^^^^^^␊
    > 4 | 	});␊
        | ^^^^ Prefer specifying an old error as \`cause\` option when rethrowing the error.␊
      5 | })␊
      6 | .catch(onError);␊
    `
