# Snapshot report for `test/prefer-error-cause.mjs`

The actual snapshot is saved in `prefer-error-cause.mjs.snap`.

Generated by [AVA](https://avajs.dev).

## Invalid #1
      1 | try {} catch { throw new Error('oops'); }

> Output

    `␊
      1 | try {} catch (error) { throw new Error('oops', {cause: error}); }␊
    `

> Error 1/1

    `␊
    > 1 | try {} catch { throw new Error('oops'); }␊
        |        ^^^^^^^^^^^^^^^^^^^^^^^^^^^^^^^^^^ Prefer specifying an old error as \`cause\` option where rethrowing the error.␊
    `

## Invalid #2
      1 | try {} catch (oldError) { throw new Error('oops'); }

> Output

    `␊
      1 | try {} catch (oldError) { throw new Error('oops', {cause: oldError}); }␊
    `

> Error 1/1

    `␊
    > 1 | try {} catch (oldError) { throw new Error('oops'); }␊
        |        ^^^^^^^^^^^^^^^^^^^^^^^^^^^^^^^^^^^^^^^^^^^^^ Prefer specifying an old error as \`cause\` option where rethrowing the error.␊
    `

## Invalid #3
      1 | try {} catch (oldError) { throw new Error(); }

> Error 1/1

    `␊
    > 1 | try {} catch (oldError) { throw new Error(); }␊
        |        ^^^^^^^^^^^^^^^^^^^^^^^^^^^^^^^^^^^^^^^ Prefer specifying an old error as \`cause\` option where rethrowing the error.␊
    `

## Invalid #4
      1 | try {} catch (oldError) { throw new Error; }

> Error 1/1

    `␊
    > 1 | try {} catch (oldError) { throw new Error; }␊
        |        ^^^^^^^^^^^^^^^^^^^^^^^^^^^^^^^^^^^^^ Prefer specifying an old error as \`cause\` option where rethrowing the error.␊
    `

## Invalid #5
      1 | try {} catch { throw new Error(); }

> Error 1/1

    `␊
    > 1 | try {} catch { throw new Error(); }␊
        |        ^^^^^^^^^^^^^^^^^^^^^^^^^^^^ Prefer specifying an old error as \`cause\` option where rethrowing the error.␊
    `

## Invalid #6
      1 | try {} catch { throw new Error; }

> Error 1/1

    `␊
    > 1 | try {} catch { throw new Error; }␊
        |        ^^^^^^^^^^^^^^^^^^^^^^^^^^ Prefer specifying an old error as \`cause\` option where rethrowing the error.␊
    `

## Invalid #7
      1 | try {} catch ({}) { throw new Error('oops'); }

> Error 1/1

    `␊
    > 1 | try {} catch ({}) { throw new Error('oops'); }␊
        |        ^^^^^^^^^^^^^^^^^^^^^^^^^^^^^^^^^^^^^^^ Prefer specifying an old error as \`cause\` option where rethrowing the error.␊
    `

## Invalid #8
      1 | try {} catch ({error}) { throw new Error('oops'); }

> Error 1/1

    `␊
    > 1 | try {} catch ({error}) { throw new Error('oops'); }␊
        |        ^^^^^^^^^^^^^^^^^^^^^^^^^^^^^^^^^^^^^^^^^^^^ Prefer specifying an old error as \`cause\` option where rethrowing the error.␊
    `

## Invalid #9
      1 | try {} catch ({error}) { throw new Error('oops', {cause: error}); }

> Error 1/1

    `␊
    > 1 | try {} catch ({error}) { throw new Error('oops', {cause: error}); }␊
        |        ^^^^^^^^^^^^^^^^^^^^^^^^^^^^^^^^^^^^^^^^^^^^^^^^^^^^^^^^^^^^ Prefer specifying an old error as \`cause\` option where rethrowing the error.␊
    `

## Invalid #10
      1 | try {} catch (oldError) {
      2 | 	throw new Error('oops', {cause: someTypo});
      3 | }

> Output

    `␊
      1 | try {} catch (oldError) {␊
      2 | 	throw new Error('oops', {cause: oldError});␊
      3 | }␊
    `

> Error 1/1

    `␊
    > 1 | try {} catch (oldError) {␊
        |        ^^^^^^^^^^^^^^^^^^␊
    > 2 | 	throw new Error('oops', {cause: someTypo});␊
        | ^^^^^^^^^^^^^^^^^^^^^^^^^^^^^^^^^^^^^^^^^^^^␊
    > 3 | }␊
        | ^^ Prefer specifying an old error as \`cause\` option where rethrowing the error.␊
    `

## Invalid #11
      1 | try {} catch (oldError) {
      2 | 	throw new Error('oops', {cause: someTypo, other: 'abc'});
      3 | }

> Output

    `␊
      1 | try {} catch (oldError) {␊
      2 | 	throw new Error('oops', {cause: oldError, other: 'abc'});␊
      3 | }␊
    `

> Error 1/1

    `␊
    > 1 | try {} catch (oldError) {␊
        |        ^^^^^^^^^^^^^^^^^^␊
    > 2 | 	throw new Error('oops', {cause: someTypo, other: 'abc'});␊
        | ^^^^^^^^^^^^^^^^^^^^^^^^^^^^^^^^^^^^^^^^^^^^^^^^^^^^^^^^^^␊
    > 3 | }␊
        | ^^ Prefer specifying an old error as \`cause\` option where rethrowing the error.␊
    `

## Invalid #12
      1 | try {} catch {
      2 | 	throw new Error('oops', {other: 'abc'});
      3 | }

> Output

    `␊
      1 | try {} catch (error) {␊
      2 | 	throw new Error('oops', {other: 'abc', cause: error});␊
      3 | }␊
    `

> Error 1/1

    `␊
    > 1 | try {} catch {␊
        |        ^^^^^^^␊
    > 2 | 	throw new Error('oops', {other: 'abc'});␊
        | ^^^^^^^^^^^^^^^^^^^^^^^^^^^^^^^^^^^^^^^^^␊
    > 3 | }␊
        | ^^ Prefer specifying an old error as \`cause\` option where rethrowing the error.␊
    `

## Invalid #13
      1 | try {} catch {
      2 | 	const error = new Error('oops');
      3 | 	throw error;
      4 | }

> Output

    `␊
      1 | try {} catch (error) {␊
      2 | 	const error = new Error('oops');␊
      3 | 	throw error;␊
      4 | }␊
    `

> Error 1/1

    `␊
    > 1 | try {} catch {␊
        |        ^^^^^^^␊
    > 2 | 	const error = new Error('oops');␊
        | ^^^^^^^^^^^^^^^^^^^^^^^^^^^^^^^^^␊
    > 3 | 	throw error;␊
        | ^^^^^^^^^^^^^^^^^^^^^^^^^^^^^^^^^␊
    > 4 | }␊
        | ^^ Prefer specifying an old error as \`cause\` option where rethrowing the error.␊
    `

## Invalid #14
      1 | try {} catch (oldError) {
      2 | 	const error = new Error('oops');
      3 | 	throw error;
      4 | }

> Output

    `␊
      1 | try {} catch (oldError) {␊
      2 | 	const error = new Error('oops', {cause: oldError});␊
      3 | 	throw error;␊
      4 | }␊
    `

> Error 1/1

    `␊
    > 1 | try {} catch (oldError) {␊
        |        ^^^^^^^^^^^^^^^^^^␊
    > 2 | 	const error = new Error('oops');␊
        | ^^^^^^^^^^^^^^^^^^^^^^^^^^^^^^^^^␊
    > 3 | 	throw error;␊
        | ^^^^^^^^^^^^^^^^^^^^^^^^^^^^^^^^^␊
    > 4 | }␊
        | ^^ Prefer specifying an old error as \`cause\` option where rethrowing the error.␊
    `

## Invalid #15
      1 | try {} catch (oldError) {
      2 | 	const error = new Error('oops', {cause: someTypo});
      3 | 	throw error;
      4 | }

> Output

    `␊
      1 | try {} catch (oldError) {␊
      2 | 	const error = new Error('oops', {cause: oldError});␊
      3 | 	throw error;␊
      4 | }␊
    `

> Error 1/1

    `␊
    > 1 | try {} catch (oldError) {␊
        |        ^^^^^^^^^^^^^^^^^^␊
    > 2 | 	const error = new Error('oops', {cause: someTypo});␊
        | ^^^^^^^^^^^^^^^^^^^^^^^^^^^^^^^^^^^^^^^^^^^^^^^^^^^^␊
    > 3 | 	throw error;␊
        | ^^^^^^^^^^^^^^^^^^^^^^^^^^^^^^^^^^^^^^^^^^^^^^^^^^^^␊
    > 4 | }␊
        | ^^ Prefer specifying an old error as \`cause\` option where rethrowing the error.␊
    `

## Invalid #16
      1 | try {
      2 |
      3 | } catch {
      4 | 	try {
      5 |
      6 | 	} catch (oldError2) {
      7 | 		throw new Error(oldError2);
      8 | 	}
      9 | }

> Output

    `␊
      1 | try {␊
      2 |␊
      3 | } catch {␊
      4 | 	try {␊
      5 |␊
      6 | 	} catch (oldError2) {␊
      7 | 		throw new Error(oldError2, {cause: oldError2});␊
      8 | 	}␊
      9 | }␊
    `

> Error 1/1

    `␊
      1 | try {␊
      2 |␊
      3 | } catch {␊
      4 | 	try {␊
      5 |␊
    > 6 | 	} catch (oldError2) {␊
        | 	  ^^^^^^^^^^^^^^^^^^^␊
    > 7 | 		throw new Error(oldError2);␊
        | ^^^^^^^^^^^^^^^^^^^^^^^^^^^^^␊
    > 8 | 	}␊
        | ^^^ Prefer specifying an old error as \`cause\` option where rethrowing the error.␊
      9 | }␊
    `

## Invalid #17
       1 | try {
       2 |
       3 | } catch (oldError1) {
       4 | 	throw new Error(oldError1);
       5 | 	try {
       6 |
       7 | 	} catch (oldError2) {
       8 | 		throw new Error(oldError2);
       9 | 	}
      10 | }

> Output

    `␊
       1 | try {␊
       2 |␊
       3 | } catch (oldError1) {␊
       4 | 	throw new Error(oldError1, {cause: oldError1});␊
       5 | 	try {␊
       6 |␊
       7 | 	} catch (oldError2) {␊
       8 | 		throw new Error(oldError2, {cause: oldError2});␊
       9 | 	}␊
      10 | }␊
    `

> Error 1/2

    `␊
       1 | try {␊
       2 |␊
    >  3 | } catch (oldError1) {␊
         |   ^^^^^^^^^^^^^^^^^^^␊
    >  4 | 	throw new Error(oldError1);␊
         | ^^^^^^^^^^^^^^^^^^^^^^^^^^^^␊
    >  5 | 	try {␊
         | ^^^^^^^^^^^^^^^^^^^^^^^^^^^^␊
    >  6 |␊
         | ^^^^^^^^^^^^^^^^^^^^^^^^^^^^␊
    >  7 | 	} catch (oldError2) {␊
         | ^^^^^^^^^^^^^^^^^^^^^^^^^^^^␊
    >  8 | 		throw new Error(oldError2);␊
         | ^^^^^^^^^^^^^^^^^^^^^^^^^^^^␊
    >  9 | 	}␊
         | ^^^^^^^^^^^^^^^^^^^^^^^^^^^^␊
    > 10 | }␊
         | ^^ Prefer specifying an old error as \`cause\` option where rethrowing the error.␊
    `

> Error 2/2

    `␊
       1 | try {␊
       2 |␊
       3 | } catch (oldError1) {␊
       4 | 	throw new Error(oldError1);␊
       5 | 	try {␊
       6 |␊
    >  7 | 	} catch (oldError2) {␊
         | 	  ^^^^^^^^^^^^^^^^^^^␊
    >  8 | 		throw new Error(oldError2);␊
         | ^^^^^^^^^^^^^^^^^^^^^^^^^^^^^␊
    >  9 | 	}␊
         | ^^^ Prefer specifying an old error as \`cause\` option where rethrowing the error.␊
      10 | }␊
    `

## Invalid #18
      1 | try {
      2 |
      3 | } catch {
      4 | 	try {
      5 |
      6 | 	} catch (oldError2) {
      7 | 		throw new Error(oldError1);
      8 | 	}
      9 | }

> Output

    `␊
      1 | try {␊
      2 |␊
      3 | } catch {␊
      4 | 	try {␊
      5 |␊
      6 | 	} catch (oldError2) {␊
      7 | 		throw new Error(oldError1, {cause: oldError2});␊
      8 | 	}␊
      9 | }␊
    `

> Error 1/1

    `␊
      1 | try {␊
      2 |␊
      3 | } catch {␊
      4 | 	try {␊
      5 |␊
    > 6 | 	} catch (oldError2) {␊
        | 	  ^^^^^^^^^^^^^^^^^^^␊
    > 7 | 		throw new Error(oldError1);␊
        | ^^^^^^^^^^^^^^^^^^^^^^^^^^^^^␊
    > 8 | 	}␊
        | ^^^ Prefer specifying an old error as \`cause\` option where rethrowing the error.␊
      9 | }␊
    `

## Invalid #19
      1 | try {
      2 |
      3 | } catch (oldError) {
      4 | 	try {
      5 |
      6 | 	} catch {
      7 | 		throw oldError;
      8 | 	}
      9 | }

> Error 1/1

    `␊
      1 | try {␊
      2 |␊
      3 | } catch (oldError) {␊
      4 | 	try {␊
      5 |␊
    > 6 | 	} catch {␊
        | 	  ^^^^^^^␊
    > 7 | 		throw oldError;␊
        | ^^^^^^^^^^^^^^^^^␊
    > 8 | 	}␊
        | ^^^ Prefer specifying an old error as \`cause\` option where rethrowing the error.␊
      9 | }␊
    `

## Invalid #20
      1 | try {} catch (oldError) {
      2 | 	throw new CustomError('oops', {}, {cause: someTypo});
      3 | }

> Output

    `␊
      1 | try {} catch (oldError) {␊
      2 | 	throw new CustomError('oops', {}, {cause: oldError});␊
      3 | }␊
    `

> Error 1/1

    `␊
    > 1 | try {} catch (oldError) {␊
        |        ^^^^^^^^^^^^^^^^^^␊
    > 2 | 	throw new CustomError('oops', {}, {cause: someTypo});␊
        | ^^^^^^^^^^^^^^^^^^^^^^^^^^^^^^^^^^^^^^^^^^^^^^^^^^^^^^␊
    > 3 | }␊
        | ^^ Prefer specifying an old error as \`cause\` option where rethrowing the error.␊
    `

## Invalid #21
      1 | try {} catch (oldError) {
      2 | 	throw new CustomError('oops', {}, {cause: someTypo});
      3 | }

> Output

    `␊
      1 | try {} catch (oldError) {␊
      2 | 	throw new CustomError('oops', {}, {cause: oldError});␊
      3 | }␊
    `

> Error 1/1

    `␊
    > 1 | try {} catch (oldError) {␊
        |        ^^^^^^^^^^^^^^^^^^␊
    > 2 | 	throw new CustomError('oops', {}, {cause: someTypo});␊
        | ^^^^^^^^^^^^^^^^^^^^^^^^^^^^^^^^^^^^^^^^^^^^^^^^^^^^^^␊
    > 3 | }␊
        | ^^ Prefer specifying an old error as \`cause\` option where rethrowing the error.␊
    `

## Invalid #22
      1 | try {
      2 | } catch (oldError) {
      3 | 	throw new CustomError('oops', { url });
      4 | }

> Output

    `␊
      1 | try {␊
      2 | } catch (oldError) {␊
      3 | 	throw new CustomError('oops', { url , cause: oldError});␊
      4 | }␊
    `

> Error 1/1

    `␊
      1 | try {␊
    > 2 | } catch (oldError) {␊
        |   ^^^^^^^^^^^^^^^^^^␊
    > 3 | 	throw new CustomError('oops', { url });␊
        | ^^^^^^^^^^^^^^^^^^^^^^^^^^^^^^^^^^^^^^^^␊
    > 4 | }␊
        | ^^ Prefer specifying an old error as \`cause\` option where rethrowing the error.␊
    `

## Invalid #23
      1 | try {
      2 | } catch (oldError) {
      3 | 	throw new CustomError('oops', {}, {url});
      4 | }

> Output

    `␊
      1 | try {␊
      2 | } catch (oldError) {␊
      3 | 	throw new CustomError('oops', {}, {url, cause: oldError});␊
      4 | }␊
    `

> Error 1/1

    `␊
      1 | try {␊
    > 2 | } catch (oldError) {␊
        |   ^^^^^^^^^^^^^^^^^^␊
    > 3 | 	throw new CustomError('oops', {}, {url});␊
        | ^^^^^^^^^^^^^^^^^^^^^^^^^^^^^^^^^^^^^^^^^^␊
    > 4 | }␊
        | ^^ Prefer specifying an old error as \`cause\` option where rethrowing the error.␊
    `

## Invalid #24
      1 | try {
      2 | } catch (oldError) {
      3 | 	throw new CustomError('oops', {}, {url: 'abc'});
      4 | }

> Output

    `␊
      1 | try {␊
      2 | } catch (oldError) {␊
      3 | 	throw new CustomError('oops', {}, {url: 'abc', cause: oldError});␊
      4 | }␊
    `

> Error 1/1

    `␊
      1 | try {␊
    > 2 | } catch (oldError) {␊
        |   ^^^^^^^^^^^^^^^^^^␊
    > 3 | 	throw new CustomError('oops', {}, {url: 'abc'});␊
        | ^^^^^^^^^^^^^^^^^^^^^^^^^^^^^^^^^^^^^^^^^^^^^^^^^␊
    > 4 | }␊
        | ^^ Prefer specifying an old error as \`cause\` option where rethrowing the error.␊
    `

## Invalid #25
      1 | try {
      2 | } catch (oldError) {
      3 | 	throw new CustomError('oops', {}, {url});
      4 | }

> Output

    `␊
      1 | try {␊
      2 | } catch (oldError) {␊
      3 | 	throw new CustomError('oops', {}, {url, cause: oldError});␊
      4 | }␊
    `

> Error 1/1

    `␊
      1 | try {␊
    > 2 | } catch (oldError) {␊
        |   ^^^^^^^^^^^^^^^^^^␊
    > 3 | 	throw new CustomError('oops', {}, {url});␊
        | ^^^^^^^^^^^^^^^^^^^^^^^^^^^^^^^^^^^^^^^^^^␊
    > 4 | }␊
        | ^^ Prefer specifying an old error as \`cause\` option where rethrowing the error.␊
    `

## Invalid #26
      1 | try {
      2 | } catch (oldError) {
      3 | 	throw new CustomError('oops', {}, {});
      4 | }

> Output

    `␊
      1 | try {␊
      2 | } catch (oldError) {␊
      3 | 	throw new CustomError('oops', {}, {cause: oldError});␊
      4 | }␊
    `

> Error 1/1

    `␊
      1 | try {␊
    > 2 | } catch (oldError) {␊
        |   ^^^^^^^^^^^^^^^^^^␊
    > 3 | 	throw new CustomError('oops', {}, {});␊
        | ^^^^^^^^^^^^^^^^^^^^^^^^^^^^^^^^^^^^^^^␊
    > 4 | }␊
        | ^^ Prefer specifying an old error as \`cause\` option where rethrowing the error.␊
    `

## Invalid #27
      1 | try {} catch (oldError) {
      2 | 	let err;
      3 | 	err = new Error('oops');
      4 | 	throw err;
      5 | }

> Output

    `␊
      1 | try {} catch (oldError) {␊
      2 | 	let err;␊
      3 | 	err = new Error('oops', {cause: oldError});␊
      4 | 	throw err;␊
      5 | }␊
    `

> Error 1/1

    `␊
    > 1 | try {} catch (oldError) {␊
        |        ^^^^^^^^^^^^^^^^^^␊
    > 2 | 	let err;␊
        | ^^^^^^^^^␊
    > 3 | 	err = new Error('oops');␊
        | ^^^^^^^^^␊
    > 4 | 	throw err;␊
        | ^^^^^^^^^␊
    > 5 | }␊
        | ^^ Prefer specifying an old error as \`cause\` option where rethrowing the error.␊
    `

## Invalid #28
      1 | try {} catch (oldError) {
      2 | 	let err;
      3 | 	if (1 + 1 >= 2) {
      4 | 		err = new Error('oops');
      5 | 	} else {
      6 | 		err = new Error('oops');
      7 | 	}
      8 | 	throw err;
      9 | }

> Output

    `␊
      1 | try {} catch (oldError) {␊
      2 | 	let err;␊
      3 | 	if (1 + 1 >= 2) {␊
      4 | 		err = new Error('oops', {cause: oldError});␊
      5 | 	} else {␊
      6 | 		err = new Error('oops');␊
      7 | 	}␊
      8 | 	throw err;␊
      9 | }␊
    `

> Error 1/1

    `␊
    > 1 | try {} catch (oldError) {␊
        |        ^^^^^^^^^^^^^^^^^^␊
    > 2 | 	let err;␊
        | ^^^^^^^^^␊
    > 3 | 	if (1 + 1 >= 2) {␊
        | ^^^^^^^^^␊
    > 4 | 		err = new Error('oops');␊
        | ^^^^^^^^^␊
    > 5 | 	} else {␊
        | ^^^^^^^^^␊
    > 6 | 		err = new Error('oops');␊
        | ^^^^^^^^^␊
    > 7 | 	}␊
        | ^^^^^^^^^␊
    > 8 | 	throw err;␊
        | ^^^^^^^^^␊
    > 9 | }␊
        | ^^ Prefer specifying an old error as \`cause\` option where rethrowing the error.␊
    `

## Invalid #1
      1 | promise.catch((oldError) => { throw new Error(); });

> Error 1/1

    `␊
    > 1 | promise.catch((oldError) => { throw new Error(); });␊
        | ^^^^^^^^^^^^^^^^^^^^^^^^^^^^^^^^^^^^^^^^^^^^^^^^^^^ Prefer specifying an old error as \`cause\` option where rethrowing the error.␊
    `

## Invalid #2
      1 | promise.catch(function (oldError) { throw new Error(); });

> Error 1/1

    `␊
    > 1 | promise.catch(function (oldError) { throw new Error(); });␊
        | ^^^^^^^^^^^^^^^^^^^^^^^^^^^^^^^^^^^^^^^^^^^^^^^^^^^^^^^^^ Prefer specifying an old error as \`cause\` option where rethrowing the error.␊
    `

## Invalid #3
      1 | promise.catch((oldError) => { throw new Error; });

> Error 1/1

    `␊
    > 1 | promise.catch((oldError) => { throw new Error; });␊
        | ^^^^^^^^^^^^^^^^^^^^^^^^^^^^^^^^^^^^^^^^^^^^^^^^^ Prefer specifying an old error as \`cause\` option where rethrowing the error.␊
    `

## Invalid #4
      1 | promise.catch(function (oldError) { throw new Error; });

> Error 1/1

    `␊
    > 1 | promise.catch(function (oldError) { throw new Error; });␊
        | ^^^^^^^^^^^^^^^^^^^^^^^^^^^^^^^^^^^^^^^^^^^^^^^^^^^^^^^ Prefer specifying an old error as \`cause\` option where rethrowing the error.␊
    `

## Invalid #5
      1 | promise.catch((oldError) => { throw new Error('oops'); });

> Output

    `␊
      1 | promise.catch((oldError) => { throw new Error('oops', {cause: oldError}); });␊
    `

> Error 1/1

    `␊
    > 1 | promise.catch((oldError) => { throw new Error('oops'); });␊
        | ^^^^^^^^^^^^^^^^^^^^^^^^^^^^^^^^^^^^^^^^^^^^^^^^^^^^^^^^^ Prefer specifying an old error as \`cause\` option where rethrowing the error.␊
    `

## Invalid #6
      1 | promise.catch(function (oldError) { throw new Error('oops'); });

> Output

    `␊
      1 | promise.catch(function (oldError) { throw new Error('oops', {cause: oldError}); });␊
    `

> Error 1/1

    `␊
    > 1 | promise.catch(function (oldError) { throw new Error('oops'); });␊
        | ^^^^^^^^^^^^^^^^^^^^^^^^^^^^^^^^^^^^^^^^^^^^^^^^^^^^^^^^^^^^^^^ Prefer specifying an old error as \`cause\` option where rethrowing the error.␊
    `

## Invalid #7
      1 | promise.catch(({oldError}) => { throw new Error('oops', {cause:oldError}); });

> Error 1/1

    `␊
    > 1 | promise.catch(({oldError}) => { throw new Error('oops', {cause:oldError}); });␊
        | ^^^^^^^^^^^^^^^^^^^^^^^^^^^^^^^^^^^^^^^^^^^^^^^^^^^^^^^^^^^^^^^^^^^^^^^^^^^^^ Prefer specifying an old error as \`cause\` option where rethrowing the error.␊
    `

## Invalid #8
      1 | promise.catch(function ({oldError}) { throw new Error('oops', {cause:oldError}); });

> Error 1/1

    `␊
    > 1 | promise.catch(function ({oldError}) { throw new Error('oops', {cause:oldError}); });␊
        | ^^^^^^^^^^^^^^^^^^^^^^^^^^^^^^^^^^^^^^^^^^^^^^^^^^^^^^^^^^^^^^^^^^^^^^^^^^^^^^^^^^^ Prefer specifying an old error as \`cause\` option where rethrowing the error.␊
    `

## Invalid #9
      1 | promise.catch((oldError) => {
      2 | 	const error = new Error('oops', {cause:someTypo});
      3 | 	throw error;
      4 | });

> Output

    `␊
      1 | promise.catch((oldError) => {␊
      2 | 	const error = new Error('oops', {cause:oldError});␊
      3 | 	throw error;␊
      4 | });␊
    `

> Error 1/1

    `␊
    > 1 | promise.catch((oldError) => {␊
        | ^^^^^^^^^^^^^^^^^^^^^^^^^^^^^␊
    > 2 | 	const error = new Error('oops', {cause:someTypo});␊
        | ^^^^^^^^^^^^^^^^^^^^^^^^^^^^^^^^^^^^^^^^^^^^^^^^^^^␊
    > 3 | 	throw error;␊
        | ^^^^^^^^^^^^^^^^^^^^^^^^^^^^^^^^^^^^^^^^^^^^^^^^^^^␊
    > 4 | });␊
        | ^^^ Prefer specifying an old error as \`cause\` option where rethrowing the error.␊
    `

## Invalid #10
      1 | promise.catch(function (oldError) {
      2 | 	const error = new Error('oops', {cause:someTypo});
      3 | 	throw error;
      4 | });

> Output

    `␊
      1 | promise.catch(function (oldError) {␊
      2 | 	const error = new Error('oops', {cause:oldError});␊
      3 | 	throw error;␊
      4 | });␊
    `

> Error 1/1

    `␊
    > 1 | promise.catch(function (oldError) {␊
        | ^^^^^^^^^^^^^^^^^^^^^^^^^^^^^^^^^^^␊
    > 2 | 	const error = new Error('oops', {cause:someTypo});␊
        | ^^^^^^^^^^^^^^^^^^^^^^^^^^^^^^^^^^^^^^^^^^^^^^^^^^^␊
    > 3 | 	throw error;␊
        | ^^^^^^^^^^^^^^^^^^^^^^^^^^^^^^^^^^^^^^^^^^^^^^^^^^^␊
    > 4 | });␊
        | ^^^ Prefer specifying an old error as \`cause\` option where rethrowing the error.␊
    `

## Invalid #11
      1 | promise.catch((oldError) => {
      2 | 	const error = new Error('oops', {other: 'abc'});
      3 | 	throw error;
      4 | });

> Output

    `␊
      1 | promise.catch((oldError) => {␊
      2 | 	const error = new Error('oops', {other: 'abc', cause: oldError});␊
      3 | 	throw error;␊
      4 | });␊
    `

> Error 1/1

    `␊
    > 1 | promise.catch((oldError) => {␊
        | ^^^^^^^^^^^^^^^^^^^^^^^^^^^^^␊
    > 2 | 	const error = new Error('oops', {other: 'abc'});␊
        | ^^^^^^^^^^^^^^^^^^^^^^^^^^^^^^^^^^^^^^^^^^^^^^^^^␊
    > 3 | 	throw error;␊
        | ^^^^^^^^^^^^^^^^^^^^^^^^^^^^^^^^^^^^^^^^^^^^^^^^^␊
    > 4 | });␊
        | ^^^ Prefer specifying an old error as \`cause\` option where rethrowing the error.␊
    `

## Invalid #12
      1 | promise.catch(function (oldError) {
      2 | 	const error = new Error('oops', {other: 'abc'});
      3 | 	throw error;
      4 | });

> Output

    `␊
      1 | promise.catch(function (oldError) {␊
      2 | 	const error = new Error('oops', {other: 'abc', cause: oldError});␊
      3 | 	throw error;␊
      4 | });␊
    `

> Error 1/1

    `␊
    > 1 | promise.catch(function (oldError) {␊
        | ^^^^^^^^^^^^^^^^^^^^^^^^^^^^^^^^^^^␊
    > 2 | 	const error = new Error('oops', {other: 'abc'});␊
        | ^^^^^^^^^^^^^^^^^^^^^^^^^^^^^^^^^^^^^^^^^^^^^^^^^␊
    > 3 | 	throw error;␊
        | ^^^^^^^^^^^^^^^^^^^^^^^^^^^^^^^^^^^^^^^^^^^^^^^^^␊
    > 4 | });␊
        | ^^^ Prefer specifying an old error as \`cause\` option where rethrowing the error.␊
    `

## Invalid #13
      1 | promise.catch((oldError1) => {
      2 | 	const error1 = new Error('oops', {cause: oldError2});
      3 | 	throw error1;
      4 |
      5 | 	promise2.catch((oldError2) => {
      6 | 		const error2 = new Error('oops', {cause: oldError1});
      7 | 		throw error2;
      8 | 	});
      9 | });

> Output

    `␊
      1 | promise.catch((oldError1) => {␊
      2 | 	const error1 = new Error('oops', {cause: oldError1});␊
      3 | 	throw error1;␊
      4 |␊
      5 | 	promise2.catch((oldError2) => {␊
      6 | 		const error2 = new Error('oops', {cause: oldError2});␊
      7 | 		throw error2;␊
      8 | 	});␊
      9 | });␊
    `

> Error 1/2

    `␊
    > 1 | promise.catch((oldError1) => {␊
        | ^^^^^^^^^^^^^^^^^^^^^^^^^^^^^^␊
    > 2 | 	const error1 = new Error('oops', {cause: oldError2});␊
        | ^^^^^^^^^^^^^^^^^^^^^^^^^^^^^^^^^^^^^^^^^^^^^^^^^^^^^^␊
    > 3 | 	throw error1;␊
        | ^^^^^^^^^^^^^^^^^^^^^^^^^^^^^^^^^^^^^^^^^^^^^^^^^^^^^^␊
    > 4 |␊
        | ^^^^^^^^^^^^^^^^^^^^^^^^^^^^^^^^^^^^^^^^^^^^^^^^^^^^^^␊
    > 5 | 	promise2.catch((oldError2) => {␊
        | ^^^^^^^^^^^^^^^^^^^^^^^^^^^^^^^^^^^^^^^^^^^^^^^^^^^^^^␊
    > 6 | 		const error2 = new Error('oops', {cause: oldError1});␊
        | ^^^^^^^^^^^^^^^^^^^^^^^^^^^^^^^^^^^^^^^^^^^^^^^^^^^^^^␊
    > 7 | 		throw error2;␊
        | ^^^^^^^^^^^^^^^^^^^^^^^^^^^^^^^^^^^^^^^^^^^^^^^^^^^^^^␊
    > 8 | 	});␊
        | ^^^^^^^^^^^^^^^^^^^^^^^^^^^^^^^^^^^^^^^^^^^^^^^^^^^^^^␊
    > 9 | });␊
        | ^^^ Prefer specifying an old error as \`cause\` option where rethrowing the error.␊
    `

> Error 2/2

    `␊
      1 | promise.catch((oldError1) => {␊
      2 | 	const error1 = new Error('oops', {cause: oldError2});␊
      3 | 	throw error1;␊
      4 |␊
    > 5 | 	promise2.catch((oldError2) => {␊
        | 	^^^^^^^^^^^^^^^^^^^^^^^^^^^^^^^␊
    > 6 | 		const error2 = new Error('oops', {cause: oldError1});␊
        | ^^^^^^^^^^^^^^^^^^^^^^^^^^^^^^^^^^^^^^^^^^^^^^^^^^^^^^^␊
    > 7 | 		throw error2;␊
        | ^^^^^^^^^^^^^^^^^^^^^^^^^^^^^^^^^^^^^^^^^^^^^^^^^^^^^^^␊
    > 8 | 	});␊
        | ^^^^ Prefer specifying an old error as \`cause\` option where rethrowing the error.␊
      9 | });␊
    `

## Invalid #14
      1 | promise.catch(function (oldError1) {
      2 | 	const error1 = new Error('oops', {cause: oldError1});
      3 | 	throw error1;
      4 |
      5 | 	promise2.catch(function (oldError2) {
      6 | 		const error2 = new Error('oops', {cause: oldError1});
      7 | 		throw error2;
      8 | 	});
      9 | });

> Output

    `␊
      1 | promise.catch(function (oldError1) {␊
      2 | 	const error1 = new Error('oops', {cause: oldError1});␊
      3 | 	throw error1;␊
      4 |␊
      5 | 	promise2.catch(function (oldError2) {␊
      6 | 		const error2 = new Error('oops', {cause: oldError2});␊
      7 | 		throw error2;␊
      8 | 	});␊
      9 | });␊
    `

> Error 1/1

    `␊
      1 | promise.catch(function (oldError1) {␊
      2 | 	const error1 = new Error('oops', {cause: oldError1});␊
      3 | 	throw error1;␊
      4 |␊
    > 5 | 	promise2.catch(function (oldError2) {␊
        | 	^^^^^^^^^^^^^^^^^^^^^^^^^^^^^^^^^^^^^␊
    > 6 | 		const error2 = new Error('oops', {cause: oldError1});␊
        | ^^^^^^^^^^^^^^^^^^^^^^^^^^^^^^^^^^^^^^^^^^^^^^^^^^^^^^^␊
    > 7 | 		throw error2;␊
        | ^^^^^^^^^^^^^^^^^^^^^^^^^^^^^^^^^^^^^^^^^^^^^^^^^^^^^^^␊
    > 8 | 	});␊
        | ^^^^ Prefer specifying an old error as \`cause\` option where rethrowing the error.␊
      9 | });␊
    `

## Invalid #15
      1 | promise.catch(() => { throw new Error('oops'); });

> Output

    `␊
      1 | promise.catch((error) => { throw new Error('oops', {cause: error}); });␊
    `

> Error 1/1

    `␊
    > 1 | promise.catch(() => { throw new Error('oops'); });␊
        | ^^^^^^^^^^^^^^^^^^^^^^^^^^^^^^^^^^^^^^^^^^^^^^^^^ Prefer specifying an old error as \`cause\` option where rethrowing the error.␊
    `

## Invalid #16
      1 | promise.catch(function () { throw new Error('oops'); });

> Output

    `␊
      1 | promise.catch(function (error) { throw new Error('oops', {cause: error}); });␊
    `

> Error 1/1

    `␊
    > 1 | promise.catch(function () { throw new Error('oops'); });␊
        | ^^^^^^^^^^^^^^^^^^^^^^^^^^^^^^^^^^^^^^^^^^^^^^^^^^^^^^^ Prefer specifying an old error as \`cause\` option where rethrowing the error.␊
    `

## Invalid #17
      1 | promise.catch(function () {
      2 | 	let error;
      3 | 	error = new Error('oops');
      4 | 	throw error;
      5 | });

> Output

    `␊
      1 | promise.catch(function (error) {␊
      2 | 	let error;␊
      3 | 	error = new Error('oops');␊
      4 | 	throw error;␊
      5 | });␊
    `

> Error 1/1

    `␊
    > 1 | promise.catch(function () {␊
        | ^^^^^^^^^^^^^^^^^^^^^^^^^^^␊
    > 2 | 	let error;␊
        | ^^^^^^^^^^^␊
    > 3 | 	error = new Error('oops');␊
        | ^^^^^^^^^^^␊
    > 4 | 	throw error;␊
        | ^^^^^^^^^^^␊
    > 5 | });␊
        | ^^^ Prefer specifying an old error as \`cause\` option where rethrowing the error.␊
    `

## Invalid #18
       1 | promise.catch(function () {
       2 | 	let error;
       3 |
       4 | 	if (someCondition) {
       5 | 		error = new Error('oops');
       6 | 	} else {
       7 | 		error = new Error('oops');
       8 | 	}
       9 | 	throw error;
      10 | });

> Output

    `␊
       1 | promise.catch(function (error) {␊
       2 | 	let error;␊
       3 |␊
       4 | 	if (someCondition) {␊
       5 | 		error = new Error('oops');␊
       6 | 	} else {␊
       7 | 		error = new Error('oops');␊
       8 | 	}␊
       9 | 	throw error;␊
      10 | });␊
    `

> Error 1/1

    `␊
    >  1 | promise.catch(function () {␊
         | ^^^^^^^^^^^^^^^^^^^^^^^^^^^␊
    >  2 | 	let error;␊
         | ^^^^^^^^^^^␊
    >  3 |␊
         | ^^^^^^^^^^^␊
    >  4 | 	if (someCondition) {␊
         | ^^^^^^^^^^^␊
    >  5 | 		error = new Error('oops');␊
         | ^^^^^^^^^^^␊
    >  6 | 	} else {␊
         | ^^^^^^^^^^^␊
    >  7 | 		error = new Error('oops');␊
         | ^^^^^^^^^^^␊
    >  8 | 	}␊
         | ^^^^^^^^^^^␊
    >  9 | 	throw error;␊
         | ^^^^^^^^^^^␊
    > 10 | });␊
         | ^^^ Prefer specifying an old error as \`cause\` option where rethrowing the error.␊
    `

## Invalid #19
      1 | asyncFunc().catch(() => {
      2 | 	return promise.catch(() => {
      3 | 		throw new Error('');
      4 | 	});
      5 | });

> Output

    `␊
      1 | asyncFunc().catch(() => {␊
      2 | 	return promise.catch((error) => {␊
      3 | 		throw new Error('', {cause: error});␊
      4 | 	});␊
      5 | });␊
    `

> Error 1/1

    `␊
      1 | asyncFunc().catch(() => {␊
    > 2 | 	return promise.catch(() => {␊
        | 	       ^^^^^^^^^^^^^^^^^^^^^␊
    > 3 | 		throw new Error('');␊
        | ^^^^^^^^^^^^^^^^^^^^^^␊
    > 4 | 	});␊
        | ^^^^ Prefer specifying an old error as \`cause\` option where rethrowing the error.␊
      5 | });␊
    `

## Invalid #20
      1 | asyncFunc().catch(function () {
      2 | 	return promise.catch(function () {
      3 | 		throw new Error('');
      4 | 	});
      5 | });

> Output

    `␊
      1 | asyncFunc().catch(function () {␊
      2 | 	return promise.catch(function (error) {␊
      3 | 		throw new Error('', {cause: error});␊
      4 | 	});␊
      5 | });␊
    `

> Error 1/1

    `␊
      1 | asyncFunc().catch(function () {␊
    > 2 | 	return promise.catch(function () {␊
        | 	       ^^^^^^^^^^^^^^^^^^^^^^^^^^^␊
    > 3 | 		throw new Error('');␊
        | ^^^^^^^^^^^^^^^^^^^^^^␊
    > 4 | 	});␊
        | ^^^^ Prefer specifying an old error as \`cause\` option where rethrowing the error.␊
      5 | });␊
    `

## Invalid #21
      1 | promise1.catch(() => {
      2 | 	return promise2.catch(() => {
      3 | 		throw new Error('');
      4 | 	});
      5 | })
      6 | .catch(onError);

> Output

    `␊
      1 | promise1.catch(() => {␊
      2 | 	return promise2.catch((error) => {␊
      3 | 		throw new Error('', {cause: error});␊
      4 | 	});␊
      5 | })␊
      6 | .catch(onError);␊
    `

> Error 1/1

    `␊
      1 | promise1.catch(() => {␊
    > 2 | 	return promise2.catch(() => {␊
        | 	       ^^^^^^^^^^^^^^^^^^^^^^␊
    > 3 | 		throw new Error('');␊
        | ^^^^^^^^^^^^^^^^^^^^^^␊
    > 4 | 	});␊
        | ^^^^ Prefer specifying an old error as \`cause\` option where rethrowing the error.␊
      5 | })␊
      6 | .catch(onError);␊
    `

## Invalid #22
      1 | promise1.catch(function () {
      2 | 	return promise2.catch(function () {
      3 | 		throw new Error('');
      4 | 	});
      5 | })
      6 | .catch(onError);

> Output

    `␊
      1 | promise1.catch(function () {␊
      2 | 	return promise2.catch(function (error) {␊
      3 | 		throw new Error('', {cause: error});␊
      4 | 	});␊
      5 | })␊
      6 | .catch(onError);␊
    `

> Error 1/1

    `␊
      1 | promise1.catch(function () {␊
    > 2 | 	return promise2.catch(function () {␊
        | 	       ^^^^^^^^^^^^^^^^^^^^^^^^^^^^␊
    > 3 | 		throw new Error('');␊
        | ^^^^^^^^^^^^^^^^^^^^^^␊
    > 4 | 	});␊
        | ^^^^ Prefer specifying an old error as \`cause\` option where rethrowing the error.␊
      5 | })␊
      6 | .catch(onError);␊
    `
