# Snapshot report for `test/prefer-error-cause.mjs`

The actual snapshot is saved in `prefer-error-cause.mjs.snap`.

Generated by [AVA](https://avajs.dev).

## Invalid #1
      1 | try {} catch { throw new Error('oops'); }

> Output

    `␊
      1 | try {} catch (error) { throw new Error('oops', { cause: error }); }␊
    `

> Error 1/1

    `␊
    > 1 | try {} catch { throw new Error('oops'); }␊
        |        ^^^^^^^^^^^^^^^^^^^^^^^^^^^^^^^^^^ Prefer to add the old error as new error's \`cause\` property.␊
    `

## Invalid #2
      1 | try {} catch (error) { throw new Error('oops'); }

> Output

    `␊
      1 | try {} catch (error) { throw new Error('oops', { cause: error }); }␊
    `

> Error 1/1

    `␊
    > 1 | try {} catch (error) { throw new Error('oops'); }␊
        |        ^^^^^^^^^^^^^^^^^^^^^^^^^^^^^^^^^^^^^^^^^^ Prefer to add the old error as new error's \`cause\` property.␊
    `

## Invalid #3
      1 | try {} catch (error) { throw new Error(); }

> Error 1/1

    `␊
    > 1 | try {} catch (error) { throw new Error(); }␊
        |        ^^^^^^^^^^^^^^^^^^^^^^^^^^^^^^^^^^^^ Prefer to add the old error as new error's \`cause\` property.␊
    `

## Invalid #4
      1 | try {} catch (error) { throw new Error; }

> Error 1/1

    `␊
    > 1 | try {} catch (error) { throw new Error; }␊
        |        ^^^^^^^^^^^^^^^^^^^^^^^^^^^^^^^^^^ Prefer to add the old error as new error's \`cause\` property.␊
    `

## Invalid #5
      1 | try {} catch { throw new Error(); }

> Error 1/1

    `␊
    > 1 | try {} catch { throw new Error(); }␊
        |        ^^^^^^^^^^^^^^^^^^^^^^^^^^^^ Prefer to add the old error as new error's \`cause\` property.␊
    `

## Invalid #6
      1 | try {} catch { throw new Error; }

> Error 1/1

    `␊
    > 1 | try {} catch { throw new Error; }␊
        |        ^^^^^^^^^^^^^^^^^^^^^^^^^^ Prefer to add the old error as new error's \`cause\` property.␊
    `

## Invalid #7
      1 | try {} catch ({}) { throw new Error('oops'); }

> Error 1/1

    `␊
    > 1 | try {} catch ({}) { throw new Error('oops'); }␊
        |        ^^^^^^^^^^^^^^^^^^^^^^^^^^^^^^^^^^^^^^^ Prefer to add the old error as new error's \`cause\` property.␊
    `

## Invalid #8
      1 | try {} catch ({error}) { throw new Error('oops'); }

> Error 1/1

    `␊
    > 1 | try {} catch ({error}) { throw new Error('oops'); }␊
        |        ^^^^^^^^^^^^^^^^^^^^^^^^^^^^^^^^^^^^^^^^^^^^ Prefer to add the old error as new error's \`cause\` property.␊
    `

## Invalid #9
      1 | try {} catch ({error}) { throw new Error('oops', {cause: error}); }

> Error 1/1

    `␊
    > 1 | try {} catch ({error}) { throw new Error('oops', {cause: error}); }␊
        |        ^^^^^^^^^^^^^^^^^^^^^^^^^^^^^^^^^^^^^^^^^^^^^^^^^^^^^^^^^^^^ Prefer to add the old error as new error's \`cause\` property.␊
    `

## Invalid #10
      1 | try {} catch (err) {
      2 | 	throw new Error('oops', {cause: error});
      3 | }

> Output

    `␊
      1 | try {} catch (err) {␊
      2 | 	throw new Error('oops', {cause: err});␊
      3 | }␊
    `

> Error 1/1

    `␊
    > 1 | try {} catch (err) {␊
        |        ^^^^^^^^^^^^^␊
    > 2 | 	throw new Error('oops', {cause: error});␊
        | ^^^^^^^^^^^^^^^^^^^^^^^^^^^^^^^^^^^^^^^^^␊
    > 3 | }␊
        | ^^ Prefer to add the old error as new error's \`cause\` property.␊
    `

## Invalid #11
      1 | try {} catch (err) {
      2 | 	throw new Error('oops', {cause: error, other: 'abc'});
      3 | }

> Output

    `␊
      1 | try {} catch (err) {␊
      2 | 	throw new Error('oops', {cause: err, other: 'abc'});␊
      3 | }␊
    `

> Error 1/1

    `␊
    > 1 | try {} catch (err) {␊
        |        ^^^^^^^^^^^^^␊
    > 2 | 	throw new Error('oops', {cause: error, other: 'abc'});␊
        | ^^^^^^^^^^^^^^^^^^^^^^^^^^^^^^^^^^^^^^^^^^^^^^^^^^^^^^^␊
    > 3 | }␊
        | ^^ Prefer to add the old error as new error's \`cause\` property.␊
    `

## Invalid #12
      1 | try {} catch {
      2 | 	throw new Error('oops', {other: 'abc'});
      3 | }

> Output

    `␊
      1 | try {} catch (error) {␊
      2 | 	throw new Error('oops', {other: 'abc', cause: error});␊
      3 | }␊
    `

> Error 1/1

    `␊
    > 1 | try {} catch {␊
        |        ^^^^^^^␊
    > 2 | 	throw new Error('oops', {other: 'abc'});␊
        | ^^^^^^^^^^^^^^^^^^^^^^^^^^^^^^^^^^^^^^^^^␊
    > 3 | }␊
        | ^^ Prefer to add the old error as new error's \`cause\` property.␊
    `

## Invalid #13
      1 | try {} catch {
      2 | 	const err = new Error('oops');
      3 | 	throw err;
      4 | }

> Output

    `␊
      1 | try {} catch (error) {␊
      2 | 	const err = new Error('oops', { cause: error });␊
      3 | 	throw err;␊
      4 | }␊
    `

> Error 1/1

    `␊
    > 1 | try {} catch {␊
        |        ^^^^^^^␊
    > 2 | 	const err = new Error('oops');␊
        | ^^^^^^^^^^^^^^^^^^^^^^^^^^^^^^^␊
    > 3 | 	throw err;␊
        | ^^^^^^^^^^^^^^^^^^^^^^^^^^^^^^^␊
    > 4 | }␊
        | ^^ Prefer to add the old error as new error's \`cause\` property.␊
    `

## Invalid #14
      1 | try {} catch (error) {
      2 | 	const err = new Error('oops');
      3 | 	throw err;
      4 | }

> Output

    `␊
      1 | try {} catch (error) {␊
      2 | 	const err = new Error('oops', { cause: error });␊
      3 | 	throw err;␊
      4 | }␊
    `

> Error 1/1

    `␊
    > 1 | try {} catch (error) {␊
        |        ^^^^^^^^^^^^^^^␊
    > 2 | 	const err = new Error('oops');␊
        | ^^^^^^^^^^^^^^^^^^^^^^^^^^^^^^^␊
    > 3 | 	throw err;␊
        | ^^^^^^^^^^^^^^^^^^^^^^^^^^^^^^^␊
    > 4 | }␊
        | ^^ Prefer to add the old error as new error's \`cause\` property.␊
    `

## Invalid #15
      1 | try {} catch (error) {
      2 | 	const err = new Error('oops', {cause: error2});
      3 | 	throw err;
      4 | }

> Output

    `␊
      1 | try {} catch (error) {␊
      2 | 	const err = new Error('oops', {cause: error});␊
      3 | 	throw err;␊
      4 | }␊
    `

> Error 1/1

    `␊
    > 1 | try {} catch (error) {␊
        |        ^^^^^^^^^^^^^^^␊
    > 2 | 	const err = new Error('oops', {cause: error2});␊
        | ^^^^^^^^^^^^^^^^^^^^^^^^^^^^^^^^^^^^^^^^^^^^^^^^␊
    > 3 | 	throw err;␊
        | ^^^^^^^^^^^^^^^^^^^^^^^^^^^^^^^^^^^^^^^^^^^^^^^^␊
    > 4 | }␊
        | ^^ Prefer to add the old error as new error's \`cause\` property.␊
    `

## Invalid #16
      1 | try {
      2 |
      3 | } catch {
      4 | 	try {
      5 |
      6 | 	} catch (e2) {
      7 | 		throw new Error(e2);
      8 | 	}
      9 | }

> Output

    `␊
      1 | try {␊
      2 |␊
      3 | } catch {␊
      4 | 	try {␊
      5 |␊
      6 | 	} catch (e2) {␊
      7 | 		throw new Error(e2, { cause: e2 });␊
      8 | 	}␊
      9 | }␊
    `

> Error 1/1

    `␊
      1 | try {␊
      2 |␊
      3 | } catch {␊
      4 | 	try {␊
      5 |␊
    > 6 | 	} catch (e2) {␊
        | 	  ^^^^^^^^^^^^␊
    > 7 | 		throw new Error(e2);␊
        | ^^^^^^^^^^^^^^^^^^^^^^␊
    > 8 | 	}␊
        | ^^^ Prefer to add the old error as new error's \`cause\` property.␊
      9 | }␊
    `

## Invalid #17
       1 | try {
       2 |
       3 | } catch (e1) {
       4 | 	throw new Error(e1);
       5 | 	try {
       6 |
       7 | 	} catch (e2) {
       8 | 		throw new Error(e2);
       9 | 	}
      10 | }

> Output

    `␊
       1 | try {␊
       2 |␊
       3 | } catch (e1) {␊
       4 | 	throw new Error(e1, { cause: e1 });␊
       5 | 	try {␊
       6 |␊
       7 | 	} catch (e2) {␊
       8 | 		throw new Error(e2, { cause: e2 });␊
       9 | 	}␊
      10 | }␊
    `

> Error 1/2

    `␊
       1 | try {␊
       2 |␊
    >  3 | } catch (e1) {␊
         |   ^^^^^^^^^^^^␊
    >  4 | 	throw new Error(e1);␊
         | ^^^^^^^^^^^^^^^^^^^^^␊
    >  5 | 	try {␊
         | ^^^^^^^^^^^^^^^^^^^^^␊
    >  6 |␊
         | ^^^^^^^^^^^^^^^^^^^^^␊
    >  7 | 	} catch (e2) {␊
         | ^^^^^^^^^^^^^^^^^^^^^␊
    >  8 | 		throw new Error(e2);␊
         | ^^^^^^^^^^^^^^^^^^^^^␊
    >  9 | 	}␊
         | ^^^^^^^^^^^^^^^^^^^^^␊
    > 10 | }␊
         | ^^ Prefer to add the old error as new error's \`cause\` property.␊
    `

> Error 2/2

    `␊
       1 | try {␊
       2 |␊
       3 | } catch (e1) {␊
       4 | 	throw new Error(e1);␊
       5 | 	try {␊
       6 |␊
    >  7 | 	} catch (e2) {␊
         | 	  ^^^^^^^^^^^^␊
    >  8 | 		throw new Error(e2);␊
         | ^^^^^^^^^^^^^^^^^^^^^^␊
    >  9 | 	}␊
         | ^^^ Prefer to add the old error as new error's \`cause\` property.␊
      10 | }␊
    `

## Invalid #18
      1 | try {
      2 |
      3 | } catch {
      4 | 	try {
      5 |
      6 | 	} catch (e2) {
      7 | 		throw new Error(e1);
      8 | 	}
      9 | }

> Output

    `␊
      1 | try {␊
      2 |␊
      3 | } catch {␊
      4 | 	try {␊
      5 |␊
      6 | 	} catch (e2) {␊
      7 | 		throw new Error(e1, { cause: e2 });␊
      8 | 	}␊
      9 | }␊
    `

> Error 1/1

    `␊
      1 | try {␊
      2 |␊
      3 | } catch {␊
      4 | 	try {␊
      5 |␊
    > 6 | 	} catch (e2) {␊
        | 	  ^^^^^^^^^^^^␊
    > 7 | 		throw new Error(e1);␊
        | ^^^^^^^^^^^^^^^^^^^^^^␊
    > 8 | 	}␊
        | ^^^ Prefer to add the old error as new error's \`cause\` property.␊
      9 | }␊
    `

## Invalid #19
      1 | try {
      2 |
      3 | } catch (error) {
      4 | 	try {
      5 |
      6 | 	} catch {
      7 | 		throw error;
      8 | 	}
      9 | }

> Error 1/1

    `␊
      1 | try {␊
      2 |␊
      3 | } catch (error) {␊
      4 | 	try {␊
      5 |␊
    > 6 | 	} catch {␊
        | 	  ^^^^^^^␊
    > 7 | 		throw error;␊
        | ^^^^^^^^^^^^^^␊
    > 8 | 	}␊
        | ^^^ Prefer to add the old error as new error's \`cause\` property.␊
      9 | }␊
    `

## Invalid #20
      1 | try {} catch (error) {
      2 | 	throw new CustomError('oops', {}, {cause: err});
      3 | }

> Output

    `␊
      1 | try {} catch (error) {␊
      2 | 	throw new CustomError('oops', {}, {cause: error});␊
      3 | }␊
    `

> Error 1/1

    `␊
    > 1 | try {} catch (error) {␊
        |        ^^^^^^^^^^^^^^^␊
    > 2 | 	throw new CustomError('oops', {}, {cause: err});␊
        | ^^^^^^^^^^^^^^^^^^^^^^^^^^^^^^^^^^^^^^^^^^^^^^^^^␊
    > 3 | }␊
        | ^^ Prefer to add the old error as new error's \`cause\` property.␊
    `

## Invalid #21
      1 | try {} catch (error) {
      2 | 	throw new CustomError('oops', {}, {cause: err});
      3 | }

> Output

    `␊
      1 | try {} catch (error) {␊
      2 | 	throw new CustomError('oops', {}, {cause: error});␊
      3 | }␊
    `

> Error 1/1

    `␊
    > 1 | try {} catch (error) {␊
        |        ^^^^^^^^^^^^^^^␊
    > 2 | 	throw new CustomError('oops', {}, {cause: err});␊
        | ^^^^^^^^^^^^^^^^^^^^^^^^^^^^^^^^^^^^^^^^^^^^^^^^^␊
    > 3 | }␊
        | ^^ Prefer to add the old error as new error's \`cause\` property.␊
    `

## Invalid #22
      1 | try {
      2 | } catch (err) {
      3 | 	throw new CustomError('oops', { url });
      4 | }

> Output

    `␊
      1 | try {␊
      2 | } catch (err) {␊
      3 | 	throw new CustomError('oops', { url , cause: err});␊
      4 | }␊
    `

> Error 1/1

    `␊
      1 | try {␊
    > 2 | } catch (err) {␊
        |   ^^^^^^^^^^^^^␊
    > 3 | 	throw new CustomError('oops', { url });␊
        | ^^^^^^^^^^^^^^^^^^^^^^^^^^^^^^^^^^^^^^^^␊
    > 4 | }␊
        | ^^ Prefer to add the old error as new error's \`cause\` property.␊
    `

## Invalid #23
      1 | try {
      2 | } catch (err) {
      3 | 	throw new CustomError('oops', {}, {url});
      4 | }

> Output

    `␊
      1 | try {␊
      2 | } catch (err) {␊
      3 | 	throw new CustomError('oops', {}, {url, cause: err});␊
      4 | }␊
    `

> Error 1/1

    `␊
      1 | try {␊
    > 2 | } catch (err) {␊
        |   ^^^^^^^^^^^^^␊
    > 3 | 	throw new CustomError('oops', {}, {url});␊
        | ^^^^^^^^^^^^^^^^^^^^^^^^^^^^^^^^^^^^^^^^^^␊
    > 4 | }␊
        | ^^ Prefer to add the old error as new error's \`cause\` property.␊
    `

## Invalid #24
      1 | try {
      2 | } catch (err) {
      3 | 	throw new CustomError('oops', {}, {url: 'abc'});
      4 | }

> Output

    `␊
      1 | try {␊
      2 | } catch (err) {␊
      3 | 	throw new CustomError('oops', {}, {url: 'abc', cause: err});␊
      4 | }␊
    `

> Error 1/1

    `␊
      1 | try {␊
    > 2 | } catch (err) {␊
        |   ^^^^^^^^^^^^^␊
    > 3 | 	throw new CustomError('oops', {}, {url: 'abc'});␊
        | ^^^^^^^^^^^^^^^^^^^^^^^^^^^^^^^^^^^^^^^^^^^^^^^^^␊
    > 4 | }␊
        | ^^ Prefer to add the old error as new error's \`cause\` property.␊
    `

## Invalid #25
      1 | try {
      2 | } catch (err) {
      3 | 	throw new CustomError('oops', {}, {url});
      4 | }

> Output

    `␊
      1 | try {␊
      2 | } catch (err) {␊
      3 | 	throw new CustomError('oops', {}, {url, cause: err});␊
      4 | }␊
    `

> Error 1/1

    `␊
      1 | try {␊
    > 2 | } catch (err) {␊
        |   ^^^^^^^^^^^^^␊
    > 3 | 	throw new CustomError('oops', {}, {url});␊
        | ^^^^^^^^^^^^^^^^^^^^^^^^^^^^^^^^^^^^^^^^^^␊
    > 4 | }␊
        | ^^ Prefer to add the old error as new error's \`cause\` property.␊
    `

## Invalid #26
      1 | try {
      2 | } catch (err) {
      3 | 	throw new CustomError('oops', {}, {});
      4 | }

> Output

    `␊
      1 | try {␊
      2 | } catch (err) {␊
      3 | 	throw new CustomError('oops', {}, {cause: err});␊
      4 | }␊
    `

> Error 1/1

    `␊
      1 | try {␊
    > 2 | } catch (err) {␊
        |   ^^^^^^^^^^^^^␊
    > 3 | 	throw new CustomError('oops', {}, {});␊
        | ^^^^^^^^^^^^^^^^^^^^^^^^^^^^^^^^^^^^^^^␊
    > 4 | }␊
        | ^^ Prefer to add the old error as new error's \`cause\` property.␊
    `

## Invalid #1
      1 | promise.catch((err) => { throw new Error(); });

> Error 1/1

    `␊
    > 1 | promise.catch((err) => { throw new Error(); });␊
        | ^^^^^^^^^^^^^^^^^^^^^^^^^^^^^^^^^^^^^^^^^^^^^^ Prefer to add the old error as new error's \`cause\` property.␊
    `

## Invalid #2
      1 | promise.catch(function (err) { throw new Error(); });

> Error 1/1

    `␊
    > 1 | promise.catch(function (err) { throw new Error(); });␊
        | ^^^^^^^^^^^^^^^^^^^^^^^^^^^^^^^^^^^^^^^^^^^^^^^^^^^^ Prefer to add the old error as new error's \`cause\` property.␊
    `

## Invalid #3
      1 | promise.catch((err) => { throw new Error; });

> Error 1/1

    `␊
    > 1 | promise.catch((err) => { throw new Error; });␊
        | ^^^^^^^^^^^^^^^^^^^^^^^^^^^^^^^^^^^^^^^^^^^^ Prefer to add the old error as new error's \`cause\` property.␊
    `

## Invalid #4
      1 | promise.catch(function (err) { throw new Error; });

> Error 1/1

    `␊
    > 1 | promise.catch(function (err) { throw new Error; });␊
        | ^^^^^^^^^^^^^^^^^^^^^^^^^^^^^^^^^^^^^^^^^^^^^^^^^^ Prefer to add the old error as new error's \`cause\` property.␊
    `

## Invalid #5
      1 | promise.catch((err) => { throw new Error('oops'); });

> Output

    `␊
      1 | promise.catch((err) => { throw new Error('oops', { cause: err }); });␊
    `

> Error 1/1

    `␊
    > 1 | promise.catch((err) => { throw new Error('oops'); });␊
        | ^^^^^^^^^^^^^^^^^^^^^^^^^^^^^^^^^^^^^^^^^^^^^^^^^^^^ Prefer to add the old error as new error's \`cause\` property.␊
    `

## Invalid #6
      1 | promise.catch(function (err) { throw new Error('oops'); });

> Output

    `␊
      1 | promise.catch(function (err) { throw new Error('oops', { cause: err }); });␊
    `

> Error 1/1

    `␊
    > 1 | promise.catch(function (err) { throw new Error('oops'); });␊
        | ^^^^^^^^^^^^^^^^^^^^^^^^^^^^^^^^^^^^^^^^^^^^^^^^^^^^^^^^^^ Prefer to add the old error as new error's \`cause\` property.␊
    `

## Invalid #7
      1 | promise.catch(({err}) => { throw new Error('oops', {cause:err}); });

> Error 1/1

    `␊
    > 1 | promise.catch(({err}) => { throw new Error('oops', {cause:err}); });␊
        | ^^^^^^^^^^^^^^^^^^^^^^^^^^^^^^^^^^^^^^^^^^^^^^^^^^^^^^^^^^^^^^^^^^^ Prefer to add the old error as new error's \`cause\` property.␊
    `

## Invalid #8
      1 | promise.catch(function ({err}) { throw new Error('oops', {cause:err}); });

> Error 1/1

    `␊
    > 1 | promise.catch(function ({err}) { throw new Error('oops', {cause:err}); });␊
        | ^^^^^^^^^^^^^^^^^^^^^^^^^^^^^^^^^^^^^^^^^^^^^^^^^^^^^^^^^^^^^^^^^^^^^^^^^ Prefer to add the old error as new error's \`cause\` property.␊
    `

## Invalid #9
      1 | promise.catch((err) => {
      2 | 	const error = new Error('oops', {cause:err2});
      3 | 	throw error;
      4 | });

> Output

    `␊
      1 | promise.catch((err) => {␊
      2 | 	const error = new Error('oops', {cause:err});␊
      3 | 	throw error;␊
      4 | });␊
    `

> Error 1/1

    `␊
    > 1 | promise.catch((err) => {␊
        | ^^^^^^^^^^^^^^^^^^^^^^^^␊
    > 2 | 	const error = new Error('oops', {cause:err2});␊
        | ^^^^^^^^^^^^^^^^^^^^^^^^^^^^^^^^^^^^^^^^^^^^^^^␊
    > 3 | 	throw error;␊
        | ^^^^^^^^^^^^^^^^^^^^^^^^^^^^^^^^^^^^^^^^^^^^^^^␊
    > 4 | });␊
        | ^^^ Prefer to add the old error as new error's \`cause\` property.␊
    `

## Invalid #10
      1 | promise.catch(function (err) {
      2 | 	const error = new Error('oops', {cause:err2});
      3 | 	throw error;
      4 | });

> Output

    `␊
      1 | promise.catch(function (err) {␊
      2 | 	const error = new Error('oops', {cause:err});␊
      3 | 	throw error;␊
      4 | });␊
    `

> Error 1/1

    `␊
    > 1 | promise.catch(function (err) {␊
        | ^^^^^^^^^^^^^^^^^^^^^^^^^^^^^^␊
    > 2 | 	const error = new Error('oops', {cause:err2});␊
        | ^^^^^^^^^^^^^^^^^^^^^^^^^^^^^^^^^^^^^^^^^^^^^^^␊
    > 3 | 	throw error;␊
        | ^^^^^^^^^^^^^^^^^^^^^^^^^^^^^^^^^^^^^^^^^^^^^^^␊
    > 4 | });␊
        | ^^^ Prefer to add the old error as new error's \`cause\` property.␊
    `

## Invalid #11
      1 | promise.catch((err) => {
      2 | 	const error = new Error('oops', {other: 'abc'});
      3 | 	throw error;
      4 | });

> Output

    `␊
      1 | promise.catch((err) => {␊
      2 | 	const error = new Error('oops', {other: 'abc', cause: err});␊
      3 | 	throw error;␊
      4 | });␊
    `

> Error 1/1

    `␊
    > 1 | promise.catch((err) => {␊
        | ^^^^^^^^^^^^^^^^^^^^^^^^␊
    > 2 | 	const error = new Error('oops', {other: 'abc'});␊
        | ^^^^^^^^^^^^^^^^^^^^^^^^^^^^^^^^^^^^^^^^^^^^^^^^^␊
    > 3 | 	throw error;␊
        | ^^^^^^^^^^^^^^^^^^^^^^^^^^^^^^^^^^^^^^^^^^^^^^^^^␊
    > 4 | });␊
        | ^^^ Prefer to add the old error as new error's \`cause\` property.␊
    `

## Invalid #12
      1 | promise.catch(function (err) {
      2 | 	const error = new Error('oops', {other: 'abc'});
      3 | 	throw error;
      4 | });

> Output

    `␊
      1 | promise.catch(function (err) {␊
      2 | 	const error = new Error('oops', {other: 'abc', cause: err});␊
      3 | 	throw error;␊
      4 | });␊
    `

> Error 1/1

    `␊
    > 1 | promise.catch(function (err) {␊
        | ^^^^^^^^^^^^^^^^^^^^^^^^^^^^^^␊
    > 2 | 	const error = new Error('oops', {other: 'abc'});␊
        | ^^^^^^^^^^^^^^^^^^^^^^^^^^^^^^^^^^^^^^^^^^^^^^^^^␊
    > 3 | 	throw error;␊
        | ^^^^^^^^^^^^^^^^^^^^^^^^^^^^^^^^^^^^^^^^^^^^^^^^^␊
    > 4 | });␊
        | ^^^ Prefer to add the old error as new error's \`cause\` property.␊
    `

## Invalid #13
      1 | promise.catch((err1) => {
      2 | 	const error1 = new Error('oops', {cause: err1});
      3 | 	throw error1;
      4 |
      5 | 	promise2.catch((err2) => {
      6 | 		const error2 = new Error('oops', {cause: err1});
      7 | 		throw error2;
      8 | 	});
      9 | });

> Output

    `␊
      1 | promise.catch((err1) => {␊
      2 | 	const error1 = new Error('oops', {cause: err1});␊
      3 | 	throw error1;␊
      4 |␊
      5 | 	promise2.catch((err2) => {␊
      6 | 		const error2 = new Error('oops', {cause: err2});␊
      7 | 		throw error2;␊
      8 | 	});␊
      9 | });␊
    `

> Error 1/1

    `␊
      1 | promise.catch((err1) => {␊
      2 | 	const error1 = new Error('oops', {cause: err1});␊
      3 | 	throw error1;␊
      4 |␊
    > 5 | 	promise2.catch((err2) => {␊
        | 	^^^^^^^^^^^^^^^^^^^^^^^^^^␊
    > 6 | 		const error2 = new Error('oops', {cause: err1});␊
        | ^^^^^^^^^^^^^^^^^^^^^^^^^^^^^^^^^^^^^^^^^^^^^^^^^^␊
    > 7 | 		throw error2;␊
        | ^^^^^^^^^^^^^^^^^^^^^^^^^^^^^^^^^^^^^^^^^^^^^^^^^^␊
    > 8 | 	});␊
        | ^^^^ Prefer to add the old error as new error's \`cause\` property.␊
      9 | });␊
    `

## Invalid #14
      1 | promise.catch(function (err1) {
      2 | 	const error1 = new Error('oops', {cause: err1});
      3 | 	throw error1;
      4 |
      5 | 	promise2.catch(function (err2) {
      6 | 		const error2 = new Error('oops', {cause: err1});
      7 | 		throw error2;
      8 | 	});
      9 | });

> Output

    `␊
      1 | promise.catch(function (err1) {␊
      2 | 	const error1 = new Error('oops', {cause: err1});␊
      3 | 	throw error1;␊
      4 |␊
      5 | 	promise2.catch(function (err2) {␊
      6 | 		const error2 = new Error('oops', {cause: err2});␊
      7 | 		throw error2;␊
      8 | 	});␊
      9 | });␊
    `

> Error 1/1

    `␊
      1 | promise.catch(function (err1) {␊
      2 | 	const error1 = new Error('oops', {cause: err1});␊
      3 | 	throw error1;␊
      4 |␊
    > 5 | 	promise2.catch(function (err2) {␊
        | 	^^^^^^^^^^^^^^^^^^^^^^^^^^^^^^^^␊
    > 6 | 		const error2 = new Error('oops', {cause: err1});␊
        | ^^^^^^^^^^^^^^^^^^^^^^^^^^^^^^^^^^^^^^^^^^^^^^^^^^␊
    > 7 | 		throw error2;␊
        | ^^^^^^^^^^^^^^^^^^^^^^^^^^^^^^^^^^^^^^^^^^^^^^^^^^␊
    > 8 | 	});␊
        | ^^^^ Prefer to add the old error as new error's \`cause\` property.␊
      9 | });␊
    `

## Invalid #15
      1 | promise.catch(() => { throw new Error('oops'); });

> Output

    `␊
      1 | promise.catch((error) => { throw new Error('oops', { cause: error }); });␊
    `

> Error 1/1

    `␊
    > 1 | promise.catch(() => { throw new Error('oops'); });␊
        | ^^^^^^^^^^^^^^^^^^^^^^^^^^^^^^^^^^^^^^^^^^^^^^^^^ Prefer to add the old error as new error's \`cause\` property.␊
    `

## Invalid #16
      1 | promise.catch(function () { throw new Error('oops'); });

> Output

    `␊
      1 | promise.catch(function (error) { throw new Error('oops', { cause: error }); });␊
    `

> Error 1/1

    `␊
    > 1 | promise.catch(function () { throw new Error('oops'); });␊
        | ^^^^^^^^^^^^^^^^^^^^^^^^^^^^^^^^^^^^^^^^^^^^^^^^^^^^^^^ Prefer to add the old error as new error's \`cause\` property.␊
    `

## Invalid #17
      1 | asyncFunc().catch(() => {
      2 | 	return promise.catch(() => {
      3 | 		throw new Error('');
      4 | 	});
      5 | });

> Output

    `␊
      1 | asyncFunc().catch(() => {␊
      2 | 	return promise.catch((error) => {␊
      3 | 		throw new Error('', { cause: error });␊
      4 | 	});␊
      5 | });␊
    `

> Error 1/1

    `␊
      1 | asyncFunc().catch(() => {␊
    > 2 | 	return promise.catch(() => {␊
        | 	       ^^^^^^^^^^^^^^^^^^^^^␊
    > 3 | 		throw new Error('');␊
        | ^^^^^^^^^^^^^^^^^^^^^^␊
    > 4 | 	});␊
        | ^^^^ Prefer to add the old error as new error's \`cause\` property.␊
      5 | });␊
    `

## Invalid #18
      1 | asyncFunc().catch(function () {
      2 | 	return promise.catch(function () {
      3 | 		throw new Error('');
      4 | 	});
      5 | });

> Output

    `␊
      1 | asyncFunc().catch(function () {␊
      2 | 	return promise.catch(function (error) {␊
      3 | 		throw new Error('', { cause: error });␊
      4 | 	});␊
      5 | });␊
    `

> Error 1/1

    `␊
      1 | asyncFunc().catch(function () {␊
    > 2 | 	return promise.catch(function () {␊
        | 	       ^^^^^^^^^^^^^^^^^^^^^^^^^^^␊
    > 3 | 		throw new Error('');␊
        | ^^^^^^^^^^^^^^^^^^^^^^␊
    > 4 | 	});␊
        | ^^^^ Prefer to add the old error as new error's \`cause\` property.␊
      5 | });␊
    `

## Invalid #19
      1 | promise1.catch(() => {
      2 | 	return promise2.catch(() => {
      3 | 		throw new Error('');
      4 | 	});
      5 | })
      6 | .catch(onError);

> Output

    `␊
      1 | promise1.catch(() => {␊
      2 | 	return promise2.catch((error) => {␊
      3 | 		throw new Error('', { cause: error });␊
      4 | 	});␊
      5 | })␊
      6 | .catch(onError);␊
    `

> Error 1/1

    `␊
      1 | promise1.catch(() => {␊
    > 2 | 	return promise2.catch(() => {␊
        | 	       ^^^^^^^^^^^^^^^^^^^^^^␊
    > 3 | 		throw new Error('');␊
        | ^^^^^^^^^^^^^^^^^^^^^^␊
    > 4 | 	});␊
        | ^^^^ Prefer to add the old error as new error's \`cause\` property.␊
      5 | })␊
      6 | .catch(onError);␊
    `

## Invalid #20
      1 | promise1.catch(function () {
      2 | 	return promise2.catch(function () {
      3 | 		throw new Error('');
      4 | 	});
      5 | })
      6 | .catch(onError);

> Output

    `␊
      1 | promise1.catch(function () {␊
      2 | 	return promise2.catch(function (error) {␊
      3 | 		throw new Error('', { cause: error });␊
      4 | 	});␊
      5 | })␊
      6 | .catch(onError);␊
    `

> Error 1/1

    `␊
      1 | promise1.catch(function () {␊
    > 2 | 	return promise2.catch(function () {␊
        | 	       ^^^^^^^^^^^^^^^^^^^^^^^^^^^^␊
    > 3 | 		throw new Error('');␊
        | ^^^^^^^^^^^^^^^^^^^^^^␊
    > 4 | 	});␊
        | ^^^^ Prefer to add the old error as new error's \`cause\` property.␊
      5 | })␊
      6 | .catch(onError);␊
    `
